#VRML_SIM R2022a utf8
WorldInfo {
}
Viewpoint {
  orientation -0.2987039740571579 0.11427874895017213 0.9474789197765005 2.4460887682316352
  position 64.62256135451378 -34.30018659058612 44.91665052282072
}
TexturedBackground {
}
DirectionalLight {
  ambientIntensity 1
  direction 0.55 -0.6 -1
  intensity 2.7
  castShadows TRUE
}
Solid {
  translation 5.25 0 0
  children [
    Solid {
      children [
        Shape {
          appearance PBRAppearance {
            baseColor 1 0.682628 0.229999
            baseColorMap ImageTexture {
              url [
                "https://raw.githubusercontent.com/cyberbotics/webots/R2022a/projects/appearances/protos/textures/parquetry/light_strip_parquetry_base_color.jpg"
              ]
            }
            roughness 1
            roughnessMap ImageTexture {
              url [
                "https://raw.githubusercontent.com/cyberbotics/webots/R2022a/projects/appearances/protos/textures/parquetry/light_strip_parquetry_roughness.jpg"
              ]
            }
            metalness 0
            IBLStrength 10
            normalMap ImageTexture {
              url [
                "https://raw.githubusercontent.com/cyberbotics/webots/R2022a/projects/appearances/protos/textures/parquetry/light_strip_parquetry_normal.jpg"
              ]
            }
          }
          geometry IndexedFaceSet {
            coord Coordinate {
              point [
                -50 -50 0
                50 -50 0
                -50 50 0
                50 50 0
              ]
            }
            texCoord TextureCoordinate {
              point [
                0 0
                10 0
                0 10
                10 10
              ]
            }
            coordIndex [
              2, 0, 1, 3, -1
            ]
            texCoordIndex [
              2, 0, 1, 3, -1
            ]
          }
        }
      ]
      name "floor"
      model "floor"
      boundingObject Plane {
        size 100 100
      }
      locked TRUE
    }
    Solid {
      translation 50.005 0 0.5
      children [
        Shape {
          appearance PBRAppearance {
            baseColorMap ImageTexture {
              url [
                "https://raw.githubusercontent.com/cyberbotics/webots/R2022a/projects/appearances/protos/textures/brushed_aluminium/brushed_aluminium_base_color.jpg"
              ]
            }
            roughnessMap ImageTexture {
              url [
                "https://raw.githubusercontent.com/cyberbotics/webots/R2022a/projects/appearances/protos/textures/brushed_aluminium/brushed_aluminium_roughness.jpg"
              ]
            }
            normalMap ImageTexture {
              url [
                "https://raw.githubusercontent.com/cyberbotics/webots/R2022a/projects/appearances/protos/textures/brushed_aluminium/brushed_aluminium_normal.jpg"
              ]
            }
          }
          geometry IndexedFaceSet {
            coord Coordinate {
              point [
                -0.005 50 0.5
                0.005 50 0.5
                0.005 50 -0.5
                -0.005 50 -0.5
                -0.005 -50 -0.5
                0.005 -50 -0.5
                0.005 -50 0.5
                -0.005 -50 0.5
                -0.005 -50 0.5
                0.005 -50 0.5
                0.005 50 0.5
                -0.005 50 0.5
                0.005 -50 -0.5
                -0.005 -50 -0.5
                -0.005 50 -0.5
                0.005 50 -0.5
                -0.005 -50 -0.5
                -0.005 -50 0.5
                -0.005 50 0.5
                -0.005 50 -0.5
                0.005 -50 0.5
                0.005 -50 -0.5
                0.005 50 -0.5
                0.005 50 0.5
              ]
            }
            texCoord TextureCoordinate {
              point [
                0.0001 0.01
                0 0.01
                0 0
                0.0001 0
                0 0
                0.0001 0
                0.0001 0.01
                0 0.01
                0 0.0001
                0 0
                1 0
                1 0.0001
                0 0.0001
                0 0
                1 0
                1 0.0001
                1 0
                1 0.01
                0 0.01
                0 0
                0 0.01
                0 0
                1 0
                1 0.01
              ]
            }
            coordIndex [
              0, 1, 2, 3, -1, 4, 5, 6, 7, -1, 8, 9, 10, 11, -1, 12, 13, 14, 15, -1, 16, 17, 18, 19, -1, 20, 21, 22, 23, -1
            ]
            creaseAngle 1.5
          }
        }
      ]
      name "wall"
      model "box"
      boundingObject Box {
        size 0.01 100 1
      }
    }
    Solid {
      translation -50.005 0 0.5
      children [
        Shape {
          appearance PBRAppearance {
            baseColorMap ImageTexture {
              url [
                "https://raw.githubusercontent.com/cyberbotics/webots/R2022a/projects/appearances/protos/textures/brushed_aluminium/brushed_aluminium_base_color.jpg"
              ]
            }
            roughnessMap ImageTexture {
              url [
                "https://raw.githubusercontent.com/cyberbotics/webots/R2022a/projects/appearances/protos/textures/brushed_aluminium/brushed_aluminium_roughness.jpg"
              ]
            }
            normalMap ImageTexture {
              url [
                "https://raw.githubusercontent.com/cyberbotics/webots/R2022a/projects/appearances/protos/textures/brushed_aluminium/brushed_aluminium_normal.jpg"
              ]
            }
          }
          geometry IndexedFaceSet {
            coord Coordinate {
              point [
                -0.005 50 0.5
                0.005 50 0.5
                0.005 50 -0.5
                -0.005 50 -0.5
                -0.005 -50 -0.5
                0.005 -50 -0.5
                0.005 -50 0.5
                -0.005 -50 0.5
                -0.005 -50 0.5
                0.005 -50 0.5
                0.005 50 0.5
                -0.005 50 0.5
                0.005 -50 -0.5
                -0.005 -50 -0.5
                -0.005 50 -0.5
                0.005 50 -0.5
                -0.005 -50 -0.5
                -0.005 -50 0.5
                -0.005 50 0.5
                -0.005 50 -0.5
                0.005 -50 0.5
                0.005 -50 -0.5
                0.005 50 -0.5
                0.005 50 0.5
              ]
            }
            texCoord TextureCoordinate {
              point [
                0.0001 0.01
                0 0.01
                0 0
                0.0001 0
                0 0
                0.0001 0
                0.0001 0.01
                0 0.01
                0 0.0001
                0 0
                1 0
                1 0.0001
                0 0.0001
                0 0
                1 0
                1 0.0001
                1 0
                1 0.01
                0 0.01
                0 0
                0 0.01
                0 0
                1 0
                1 0.01
              ]
            }
            coordIndex [
              0, 1, 2, 3, -1, 4, 5, 6, 7, -1, 8, 9, 10, 11, -1, 12, 13, 14, 15, -1, 16, 17, 18, 19, -1, 20, 21, 22, 23, -1
            ]
            creaseAngle 1.5
          }
        }
      ]
      name "wall#2"
      model "box"
      boundingObject Box {
        size 0.01 100 1
      }
    }
    Solid {
      translation 0 50.005 0.5
      children [
        Shape {
          appearance PBRAppearance {
            baseColorMap ImageTexture {
              url [
                "https://raw.githubusercontent.com/cyberbotics/webots/R2022a/projects/appearances/protos/textures/brushed_aluminium/brushed_aluminium_base_color.jpg"
              ]
            }
            roughnessMap ImageTexture {
              url [
                "https://raw.githubusercontent.com/cyberbotics/webots/R2022a/projects/appearances/protos/textures/brushed_aluminium/brushed_aluminium_roughness.jpg"
              ]
            }
            normalMap ImageTexture {
              url [
                "https://raw.githubusercontent.com/cyberbotics/webots/R2022a/projects/appearances/protos/textures/brushed_aluminium/brushed_aluminium_normal.jpg"
              ]
            }
          }
          geometry IndexedFaceSet {
            coord Coordinate {
              point [
                -50.01 0.005 0.5
                50.01 0.005 0.5
                50.01 0.005 -0.5
                -50.01 0.005 -0.5
                -50.01 -0.005 -0.5
                50.01 -0.005 -0.5
                50.01 -0.005 0.5
                -50.01 -0.005 0.5
                -50.01 -0.005 0.5
                50.01 -0.005 0.5
                50.01 0.005 0.5
                -50.01 0.005 0.5
                50.01 -0.005 -0.5
                -50.01 -0.005 -0.5
                -50.01 0.005 -0.5
                50.01 0.005 -0.5
                -50.01 -0.005 -0.5
                -50.01 -0.005 0.5
                -50.01 0.005 0.5
                -50.01 0.005 -0.5
                50.01 -0.005 0.5
                50.01 -0.005 -0.5
                50.01 0.005 -0.5
                50.01 0.005 0.5
              ]
            }
            texCoord TextureCoordinate {
              point [
                1 0.009998000399920017
                0 0.009998000399920017
                0 0
                1 0
                0 0
                1 0
                1 0.009998000399920017
                0 0.009998000399920017
                0 1
                0 0
                9.998000399920017e-05 0
                9.998000399920017e-05 1
                0 1
                0 0
                9.998000399920017e-05 0
                9.998000399920017e-05 1
                9.998000399920017e-05 0
                9.998000399920017e-05 0.009998000399920017
                0 0.009998000399920017
                0 0
                0 0.009998000399920017
                0 0
                9.998000399920017e-05 0
                9.998000399920017e-05 0.009998000399920017
              ]
            }
            coordIndex [
              0, 1, 2, 3, -1, 4, 5, 6, 7, -1, 8, 9, 10, 11, -1, 12, 13, 14, 15, -1, 16, 17, 18, 19, -1, 20, 21, 22, 23, -1
            ]
            creaseAngle 1.5
          }
        }
      ]
      name "wall#3"
      model "box"
      boundingObject Box {
        size 100.02 0.01 1
      }
    }
    Solid {
      translation 0 -50.005 0.5
      children [
        Shape {
          appearance PBRAppearance {
            baseColorMap ImageTexture {
              url [
                "https://raw.githubusercontent.com/cyberbotics/webots/R2022a/projects/appearances/protos/textures/brushed_aluminium/brushed_aluminium_base_color.jpg"
              ]
            }
            roughnessMap ImageTexture {
              url [
                "https://raw.githubusercontent.com/cyberbotics/webots/R2022a/projects/appearances/protos/textures/brushed_aluminium/brushed_aluminium_roughness.jpg"
              ]
            }
            normalMap ImageTexture {
              url [
                "https://raw.githubusercontent.com/cyberbotics/webots/R2022a/projects/appearances/protos/textures/brushed_aluminium/brushed_aluminium_normal.jpg"
              ]
            }
          }
          geometry IndexedFaceSet {
            coord Coordinate {
              point [
                -50.01 0.005 0.5
                50.01 0.005 0.5
                50.01 0.005 -0.5
                -50.01 0.005 -0.5
                -50.01 -0.005 -0.5
                50.01 -0.005 -0.5
                50.01 -0.005 0.5
                -50.01 -0.005 0.5
                -50.01 -0.005 0.5
                50.01 -0.005 0.5
                50.01 0.005 0.5
                -50.01 0.005 0.5
                50.01 -0.005 -0.5
                -50.01 -0.005 -0.5
                -50.01 0.005 -0.5
                50.01 0.005 -0.5
                -50.01 -0.005 -0.5
                -50.01 -0.005 0.5
                -50.01 0.005 0.5
                -50.01 0.005 -0.5
                50.01 -0.005 0.5
                50.01 -0.005 -0.5
                50.01 0.005 -0.5
                50.01 0.005 0.5
              ]
            }
            texCoord TextureCoordinate {
              point [
                1 0.009998000399920017
                0 0.009998000399920017
                0 0
                1 0
                0 0
                1 0
                1 0.009998000399920017
                0 0.009998000399920017
                0 1
                0 0
                9.998000399920017e-05 0
                9.998000399920017e-05 1
                0 1
                0 0
                9.998000399920017e-05 0
                9.998000399920017e-05 1
                9.998000399920017e-05 0
                9.998000399920017e-05 0.009998000399920017
                0 0.009998000399920017
                0 0
                0 0.009998000399920017
                0 0
                9.998000399920017e-05 0
                9.998000399920017e-05 0.009998000399920017
              ]
            }
            coordIndex [
              0, 1, 2, 3, -1, 4, 5, 6, 7, -1, 8, 9, 10, 11, -1, 12, 13, 14, 15, -1, 16, 17, 18, 19, -1, 20, 21, 22, 23, -1
            ]
            creaseAngle 1.5
          }
        }
      ]
      name "wall#4"
      model "box"
      boundingObject Box {
        size 100.02 0.01 1
      }
    }
  ]
  name "rectangle arena"
  model "rectangle arena"
}
LincolnMKZSimple {
  translation -6.87678 -1.53763 0.4
  rotation 0 0 1 1.0472
  name "vehicle(4)"
}
Robot {
  translation -12 0 0
  rotation 3.59591e-07 -1.02107e-07 1 0
  children [
    Lidar {
      translation -4.40288e-06 0 1.8
      rotation 0 1 0 3.46682e-06
      horizontalResolution 520
      fieldOfView 1
      verticalFieldOfView 0.7
      numberOfLayers 100
      maxRange 7
    }
    Group {
    }
    Shape {
      appearance PBRAppearance {
        baseColor 1 0 0
        roughness 0.3
        metalness 0
      }
      geometry IndexedFaceSet {
        coord Coordinate {
          point [
            -0.215 0.1 0.059
            -0.215 -0.1 0.059
            -0.185 -0.135 0.059
            0.095 -0.135 0.059
            0.11 -0.08 0.059
            0.11 0.08 0.059
            0.095 0.135 0.059
            -0.185 0.135 0.059
            -0.215 0.1 0.059
            -0.215 0.1 0.234
            -0.215 -0.1 0.234
            -0.185 -0.135 0.234
            0.095 -0.135 0.234
            0.11 -0.08 0.234
            0.11 0.08 0.234
            0.095 0.135 0.234
            -0.185 0.135 0.234
            -0.215 0.1 0.234
          ]
        }
        coordIndex [
          8, 7, 6, 5, 4, 3, 2, 1, 0, -1, 9, 10, 11, 12, 13, 14, 15, 16, 17, -1, 0, 1, 10, 9, -1, 1, 2, 11, 10, -1, 2, 3, 12, 11, -1, 3, 4, 13, 12, -1, 4, 5, 14, 13, -1, 5, 6, 15, 14, -1, 6, 7, 16, 15, -1, 7, 8, 17, 16, -1
        ]
      }
    }
    Shape {
      appearance PBRAppearance {
        baseColor 0.636415 0.655556 0.655556
        roughness 0.3
        metalness 0
      }
      geometry IndexedFaceSet {
        coord Coordinate {
          point [
            0.174 0 0.234, 0.166 0.056 0.234, 0.145 0.107 0.234, 0.112 0.155 0.234, 0.064 0.19 0.234, -0.074 0.19 0.234, -0.096 0.16 0.234, -0.151 0.16 0.234, -0.2 0.155 0.234, -0.236 0.107 0.234, -0.256 0.056 0.234, -0.264 0 0.234, -0.256 -0.056 0.234, -0.236 -0.107 0.234, -0.2 -0.155 0.234, -0.151 -0.16 0.234, -0.096 -0.16 0.234, -0.074 -0.19 0.234, 0.064 -0.19 0.234, 0.112 -0.155 0.234, 0.145 -0.107 0.234, 0.166 -0.056 0.234, 0.174 0 0.234, 0.174 0 0.245, 0.166 0.056 0.245, 0.145 0.107 0.245, 0.112 0.155 0.245, 0.064 0.19 0.245, -0.074 0.19 0.245, -0.096 0.16 0.245, -0.151 0.16 0.245, -0.2 0.155 0.245, -0.236 0.107 0.245, -0.256 0.056 0.245, -0.264 0 0.245, -0.256 -0.056 0.245, -0.236 -0.107 0.245, -0.2 -0.155 0.245, -0.151 -0.16 0.245, -0.096 -0.16 0.245, -0.074 -0.19 0.245, 0.064 -0.19 0.245, 0.112 -0.155 0.245, 0.145 -0.107 0.245, 0.166 -0.056 0.245, 0.174 0 0.245
          ]
        }
        coordIndex [
          22, 21, 20, 19, 18, 17, 16, 15, 14, 13, 12, 11, 10, 9, 8, 7, 6, 5, 4, 3, 2, 1, 0, -1, 23, 24, 25, 26, 27, 28, 29, 30, 31, 32, 33, 34, 35, 36, 37, 38, 39, 40, 41, 42, 43, 44, 45, -1, 0, 1, 24, 23, -1, 1, 2, 25, 24, -1, 2, 3, 26, 25, -1, 3, 4, 27, 26, -1, 4, 5, 28, 27, -1, 5, 6, 29, 28, -1, 6, 7, 30, 29, -1, 7, 8, 31, 30, -1, 8, 9, 32, 31, -1, 9, 10, 33, 32, -1, 10, 11, 34, 33, -1, 11, 12, 35, 34, -1, 12, 13, 36, 35, -1, 13, 14, 37, 36, -1, 14, 15, 38, 37, -1, 15, 16, 39, 38, -1, 16, 17, 40, 39, -1, 17, 18, 41, 40, -1, 18, 19, 42, 41, -1, 19, 20, 43, 42, -1, 20, 21, 44, 43, -1, 21, 22, 45, 44, -1
        ]
      }
    }
    HingeJoint {
      jointParameters HingeJointParameters {
        axis 0 1 0
        anchor 0 0 0.0825
      }
      device [
        RotationalMotor {
          name "left wheel motor"
        }
        PositionSensor {
          name "left wheel sensor"
        }
      ]
      endPoint Solid {
        translation -0.00863592 0.1603 0.0774581
        rotation 0.2526839701134262 -0.2526839701134262 -0.9339708895331986 1.639053
        children [
          DEF WHEEL Transform {
            rotation 0.577656895078166 0.5771968951617173 -0.5771968951617173 -2.093935
            children [
              Shape {
                appearance PBRAppearance {
                  baseColor 0.0037037 0.0037037 0.0037037
                  roughness 0.3
                  metalness 0
                }
                geometry Cylinder {
                  height 0.037
                  radius 0.0825
                }
              }
            ]
          }
        ]
        name "left wheel"
        boundingObject USE WHEEL
      }
    }
    HingeJoint {
      jointParameters HingeJointParameters {
        axis 0 1 0
        anchor 0 0 0.0825
      }
      device [
        RotationalMotor {
          name "right wheel motor"
        }
        PositionSensor {
          name "right wheel sensor"
        }
      ]
      endPoint Solid {
        translation 0 -0.1603 0.0825
        rotation 0.6879677669702216 -0.6879677669702216 -0.23108592172612774 2.687394
        children [
          USE WHEEL
        ]
        name "right wheel"
        boundingObject USE WHEEL
      }
    }
    Shape {
      appearance PBRAppearance {
        baseColor 1 0 0
        roughness 0.3
        metalness 0
      }
      geometry IndexedFaceSet {
        coord Coordinate {
          point [
            0.046 -0.136 0.184
            0.096 -0.136 0.184
            0.134 -0.101 0.184
            0.159 -0.054 0.184
            0.168 0 0.184
            0.159 0.054 0.184
            0.134 0.101 0.184
            0.096 0.136 0.184
            0.046 0.136 0.184
            0.043 -0.136 0.184
            0.046 -0.136 0.234
            0.096 -0.136 0.234
            0.134 -0.101 0.234
            0.159 -0.054 0.234
            0.168 0 0.234
            0.159 0.054 0.234
            0.134 0.101 0.234
            0.096 0.136 0.234
            0.046 0.136 0.234
            0.043 -0.136 0.234
          ]
        }
        coordIndex [
          9, 8, 7, 6, 5, 4, 3, 2, 1, 0, -1, 10, 11, 12, 13, 14, 15, 16, 17, 18, 19, -1, 0, 1, 11, 10, -1, 1, 2, 12, 11, -1, 2, 3, 13, 12, -1, 3, 4, 14, 13, -1, 4, 5, 15, 14, -1, 5, 6, 16, 15, -1, 6, 7, 17, 16, -1, 7, 8, 18, 17, -1, 8, 9, 19, 18, -1, 9, 0, 10, 19, -1
        ]
      }
    }
    Shape {
      appearance PBRAppearance {
        baseColor 1 0 0
        roughness 0.3
        metalness 0
      }
      geometry IndexedFaceSet {
        coord Coordinate {
          point [
            -0.135 0.136 0.184
            -0.185 0.136 0.184
            -0.223 0.101 0.184
            -0.248 0.054 0.184
            -0.257 0 0.184
            -0.248 -0.054 0.184
            -0.223 -0.101 0.184
            -0.185 -0.136 0.184
            -0.135 -0.136 0.184
            -0.135 0.136 0.184
            -0.135 0.136 0.234
            -0.185 0.136 0.234
            -0.223 0.101 0.234
            -0.248 0.054 0.234
            -0.257 0 0.234
            -0.248 -0.054 0.234
            -0.223 -0.101 0.234
            -0.185 -0.136 0.234
            -0.135 -0.136 0.234
            -0.135 0.136 0.234
          ]
        }
        coordIndex [
          9, 8, 7, 6, 5, 4, 3, 2, 1, 0, -1, 10, 11, 12, 13, 14, 15, 16, 17, 18, 19, -1, 0, 1, 11, 10, -1, 1, 2, 12, 11, -1, 2, 3, 13, 12, -1, 3, 4, 14, 13, -1, 4, 5, 15, 14, -1, 5, 6, 16, 15, -1, 6, 7, 17, 16, -1, 7, 8, 18, 17, -1, 8, 9, 19, 18, -1
        ]
      }
    }
    Transform {
      translation -0.2147 0 0.0325
      rotation 0.5771968951617173 0.5771968951617173 0.577656895078166 -2.093935
      children [
        Shape {
          appearance PBRAppearance {
            baseColor 0.0037037 0.0037037 0.0037037
            roughness 0.3
            metalness 0
          }
          geometry Cylinder {
            height 0.024
            radius 0.0325
          }
        }
      ]
    }
    DistanceSensor {
      translation 0.164 0.027 0.209
      rotation 0 0 1 0.174203
      children [
        DEF SONAR Transform {
          rotation 0.577656895078166 0.5771968951617173 -0.5771968951617173 -2.093935
          children [
            Shape {
              appearance PBRAppearance {
                baseColor 1 1 0.0517103
                roughness 0.3
                metalness 0
              }
              geometry Cylinder {
                height 0.002
                radius 0.0175
              }
            }
          ]
        }
      ]
      name "ds0"
      lookupTable [
        0 1024 0
        0.2 1024 0.1
        0.4 0 0.1
      ]
      type "infra-red"
    }
    DistanceSensor {
      translation 0.147 0.077 0.209
      rotation 0.9352057350394192 0.25038992906003615 0.25038992906003615 1.637735
      children [
        USE SONAR
      ]
      name "ds1"
      lookupTable [
        0 1024 0
        0.2 1024 0.1
        0.4 0 0.1
      ]
      type "infra-red"
    }
    DistanceSensor {
      translation 0.116 0.118 0.209
      rotation 0.8349694730900802 0.38911822047269523 0.38911822047269523 1.750187
      children [
        USE SONAR
      ]
      name "ds2"
      lookupTable [
        0 1024 0
        0.2 1024 0.1
        0.4 0 0.1
      ]
      type "infra-red"
    }
    DistanceSensor {
      translation 0.071 0.136 0.209
      rotation 0.5779627730800116 0.5770437734408297 0.5770437734408297 2.093476
      children [
        USE SONAR
      ]
      name "ds3"
      lookupTable [
        0 1024 0
        0.2 1024 0.1
        0.4 0 0.1
      ]
      type "infra-red"
    }
    DistanceSensor {
      translation -0.16 0.136 0.209
      rotation -0.5767367732078247 -0.5776567728460501 -0.5776567728460501 -2.095315
      children [
        USE SONAR
      ]
      name "ds4"
      lookupTable [
        0 1024 0
        0.2 1024 0.1
        0.4 0 0.1
      ]
      type "infra-red"
    }
    DistanceSensor {
      translation -0.205 0.118 0.209
      rotation -0.31297577647997865 -0.6715825203713816 -0.6715825203713816 -2.534956
      children [
        USE SONAR
      ]
      name "ds5"
      lookupTable [
        0 1024 0
        0.2 1024 0.1
        0.4 0 0.1
      ]
      type "infra-red"
    }
    DistanceSensor {
      translation -0.236 0.077 0.209
      rotation -0.1860148912057814 -0.6947655936536081 -0.6947655936536081 -2.773767
      children [
        USE SONAR
      ]
      name "ds6"
      lookupTable [
        0 1024 0
        0.2 1024 0.1
        0.4 0 0.1
      ]
      type "infra-red"
    }
    DistanceSensor {
      translation -0.253 0.027 0.209
      rotation -0.06162897048037732 -0.7057626619471765 -0.7057626619471765 -3.01849
      children [
        USE SONAR
      ]
      name "ds7"
      lookupTable [
        0 1024 0
        0.2 1024 0.1
        0.4 0 0.1
      ]
      type "infra-red"
    }
    DistanceSensor {
      translation -0.253 -0.027 0.209
      rotation -0.06183904155773597 0.7057534742880195 0.7057534742880195 -3.018072
      children [
        USE SONAR
      ]
      name "ds8"
      lookupTable [
        0 1024 0
        0.2 1024 0.1
        0.4 0 0.1
      ]
      type "infra-red"
    }
    DistanceSensor {
      translation -0.236 -0.077 0.209
      rotation -0.1862280124472945 0.6947370464355309 0.6947370464355309 -2.773355
      children [
        USE SONAR
      ]
      name "ds9"
      lookupTable [
        0 1024 0
        0.2 1024 0.1
        0.4 0 0.1
      ]
      type "infra-red"
    }
    DistanceSensor {
      translation -0.205 -0.118 0.209
      rotation -0.31319385347479545 0.6715316858293465 0.6715316858293465 -2.534558
      children [
        USE SONAR
      ]
      name "ds10"
      lookupTable [
        0 1024 0
        0.2 1024 0.1
        0.4 0 0.1
      ]
      type "infra-red"
    }
    DistanceSensor {
      translation -0.16 -0.136 0.209
      rotation 0.5773502691896258 -0.5773502691896258 -0.5773502691896258 2.094395
      children [
        USE SONAR
      ]
      name "ds11"
      lookupTable [
        0 1024 0
        0.2 1024 0.1
        0.4 0 0.1
      ]
      type "infra-red"
    }
    DistanceSensor {
      translation 0.071 -0.136 0.209
      rotation 0.5773502691896258 -0.5773502691896258 -0.5773502691896258 2.094395
      children [
        USE SONAR
      ]
      name "ds12"
      lookupTable [
        0 1024 0
        0.2 1024 0.1
        0.4 0 0.1
      ]
      type "infra-red"
    }
    DistanceSensor {
      translation 0.116 -0.118 0.209
      rotation 0.8347739105773538 -0.38932795829441263 -0.38932795829441263 1.750417
      children [
        USE SONAR
      ]
      name "ds13"
      lookupTable [
        0 1024 0
        0.2 1024 0.1
        0.4 0 0.1
      ]
      type "infra-red"
    }
    DistanceSensor {
      translation 0.147 -0.077 0.209
      rotation 0.9350669359988784 -0.25064898284420567 -0.25064898284420567 1.637883
      children [
        USE SONAR
      ]
      name "ds14"
      lookupTable [
        0 1024 0
        0.2 1024 0.1
        0.4 0 0.1
      ]
      type "infra-red"
    }
    DistanceSensor {
      translation 0.164 -0.027 0.209
      rotation -0.9924098511524273 0.08695598695782032 0.08695598695782032 -1.578415
      children [
        USE SONAR
      ]
      name "ds15"
      lookupTable [
        0 1024 0
        0.2 1024 0.1
        0.4 0 0.1
      ]
      type "infra-red"
    }
  ]
  name "Pioneer 2"
  description "designed by Activmedia Robotics"
  boundingObject Transform {
    translation -0.0447 0 0.13
    rotation 0 0 1 -1.570796
    children [
      Cylinder {
        height 0.24
        radius 0.219
      }
    ]
  }
  controller ""
}
Robot {
  translation -2 0 0
  rotation -2.79442e-07 -3.25689e-08 -1 3.14159
  children [
    Lidar {
      translation 0 0 1.9
      rotation 0 1 0 0
      horizontalResolution 520
      fieldOfView 1.3
      verticalFieldOfView 0.7
      numberOfLayers 100
      maxRange 7
    }
    Group {
    }
    Shape {
      appearance PBRAppearance {
        baseColor 1 0 0
        roughness 0.3
        metalness 0
      }
      geometry IndexedFaceSet {
        coord Coordinate {
          point [
            -0.215 0.1 0.059
            -0.215 -0.1 0.059
            -0.185 -0.135 0.059
            0.095 -0.135 0.059
            0.11 -0.08 0.059
            0.11 0.08 0.059
            0.095 0.135 0.059
            -0.185 0.135 0.059
            -0.215 0.1 0.059
            -0.215 0.1 0.234
            -0.215 -0.1 0.234
            -0.185 -0.135 0.234
            0.095 -0.135 0.234
            0.11 -0.08 0.234
            0.11 0.08 0.234
            0.095 0.135 0.234
            -0.185 0.135 0.234
            -0.215 0.1 0.234
          ]
        }
        coordIndex [
          8, 7, 6, 5, 4, 3, 2, 1, 0, -1, 9, 10, 11, 12, 13, 14, 15, 16, 17, -1, 0, 1, 10, 9, -1, 1, 2, 11, 10, -1, 2, 3, 12, 11, -1, 3, 4, 13, 12, -1, 4, 5, 14, 13, -1, 5, 6, 15, 14, -1, 6, 7, 16, 15, -1, 7, 8, 17, 16, -1
        ]
      }
    }
    Shape {
      appearance PBRAppearance {
        baseColor 0.636415 0.655556 0.655556
        roughness 0.3
        metalness 0
      }
      geometry IndexedFaceSet {
        coord Coordinate {
          point [
            0.174 0 0.234, 0.166 0.056 0.234, 0.145 0.107 0.234, 0.112 0.155 0.234, 0.064 0.19 0.234, -0.074 0.19 0.234, -0.096 0.16 0.234, -0.151 0.16 0.234, -0.2 0.155 0.234, -0.236 0.107 0.234, -0.256 0.056 0.234, -0.264 0 0.234, -0.256 -0.056 0.234, -0.236 -0.107 0.234, -0.2 -0.155 0.234, -0.151 -0.16 0.234, -0.096 -0.16 0.234, -0.074 -0.19 0.234, 0.064 -0.19 0.234, 0.112 -0.155 0.234, 0.145 -0.107 0.234, 0.166 -0.056 0.234, 0.174 0 0.234, 0.174 0 0.245, 0.166 0.056 0.245, 0.145 0.107 0.245, 0.112 0.155 0.245, 0.064 0.19 0.245, -0.074 0.19 0.245, -0.096 0.16 0.245, -0.151 0.16 0.245, -0.2 0.155 0.245, -0.236 0.107 0.245, -0.256 0.056 0.245, -0.264 0 0.245, -0.256 -0.056 0.245, -0.236 -0.107 0.245, -0.2 -0.155 0.245, -0.151 -0.16 0.245, -0.096 -0.16 0.245, -0.074 -0.19 0.245, 0.064 -0.19 0.245, 0.112 -0.155 0.245, 0.145 -0.107 0.245, 0.166 -0.056 0.245, 0.174 0 0.245
          ]
        }
        coordIndex [
          22, 21, 20, 19, 18, 17, 16, 15, 14, 13, 12, 11, 10, 9, 8, 7, 6, 5, 4, 3, 2, 1, 0, -1, 23, 24, 25, 26, 27, 28, 29, 30, 31, 32, 33, 34, 35, 36, 37, 38, 39, 40, 41, 42, 43, 44, 45, -1, 0, 1, 24, 23, -1, 1, 2, 25, 24, -1, 2, 3, 26, 25, -1, 3, 4, 27, 26, -1, 4, 5, 28, 27, -1, 5, 6, 29, 28, -1, 6, 7, 30, 29, -1, 7, 8, 31, 30, -1, 8, 9, 32, 31, -1, 9, 10, 33, 32, -1, 10, 11, 34, 33, -1, 11, 12, 35, 34, -1, 12, 13, 36, 35, -1, 13, 14, 37, 36, -1, 14, 15, 38, 37, -1, 15, 16, 39, 38, -1, 16, 17, 40, 39, -1, 17, 18, 41, 40, -1, 18, 19, 42, 41, -1, 19, 20, 43, 42, -1, 20, 21, 44, 43, -1, 21, 22, 45, 44, -1
        ]
      }
    }
    HingeJoint {
      jointParameters HingeJointParameters {
        axis 0 1 0
        anchor 0 0 0.0825
      }
      device [
        RotationalMotor {
          name "left wheel motor"
        }
        PositionSensor {
          name "left wheel sensor"
        }
      ]
      endPoint Solid {
        translation -0.00863592 0.1603 0.0774581
        rotation 0.2526839701134262 -0.2526839701134262 -0.9339708895331986 1.639053
        children [
          DEF WHEEL Transform {
            rotation 0.577656895078166 0.5771968951617173 -0.5771968951617173 -2.093935
            children [
              Shape {
                appearance PBRAppearance {
                  baseColor 0.0037037 0.0037037 0.0037037
                  roughness 0.3
                  metalness 0
                }
                geometry Cylinder {
                  height 0.037
                  radius 0.0825
                }
              }
            ]
          }
        ]
        name "left wheel"
        boundingObject USE WHEEL
      }
    }
    HingeJoint {
      jointParameters HingeJointParameters {
        axis 0 1 0
        anchor 0 0 0.0825
      }
      device [
        RotationalMotor {
          name "right wheel motor"
        }
        PositionSensor {
          name "right wheel sensor"
        }
      ]
      endPoint Solid {
        translation 0 -0.1603 0.0825
        rotation 0.6879677669702216 -0.6879677669702216 -0.23108592172612774 2.687394
        children [
          USE WHEEL
        ]
        name "right wheel"
        boundingObject USE WHEEL
      }
    }
    Shape {
      appearance PBRAppearance {
        baseColor 1 0 0
        roughness 0.3
        metalness 0
      }
      geometry IndexedFaceSet {
        coord Coordinate {
          point [
            0.046 -0.136 0.184
            0.096 -0.136 0.184
            0.134 -0.101 0.184
            0.159 -0.054 0.184
            0.168 0 0.184
            0.159 0.054 0.184
            0.134 0.101 0.184
            0.096 0.136 0.184
            0.046 0.136 0.184
            0.043 -0.136 0.184
            0.046 -0.136 0.234
            0.096 -0.136 0.234
            0.134 -0.101 0.234
            0.159 -0.054 0.234
            0.168 0 0.234
            0.159 0.054 0.234
            0.134 0.101 0.234
            0.096 0.136 0.234
            0.046 0.136 0.234
            0.043 -0.136 0.234
          ]
        }
        coordIndex [
          9, 8, 7, 6, 5, 4, 3, 2, 1, 0, -1, 10, 11, 12, 13, 14, 15, 16, 17, 18, 19, -1, 0, 1, 11, 10, -1, 1, 2, 12, 11, -1, 2, 3, 13, 12, -1, 3, 4, 14, 13, -1, 4, 5, 15, 14, -1, 5, 6, 16, 15, -1, 6, 7, 17, 16, -1, 7, 8, 18, 17, -1, 8, 9, 19, 18, -1, 9, 0, 10, 19, -1
        ]
      }
    }
    Shape {
      appearance PBRAppearance {
        baseColor 1 0 0
        roughness 0.3
        metalness 0
      }
      geometry IndexedFaceSet {
        coord Coordinate {
          point [
            -0.135 0.136 0.184
            -0.185 0.136 0.184
            -0.223 0.101 0.184
            -0.248 0.054 0.184
            -0.257 0 0.184
            -0.248 -0.054 0.184
            -0.223 -0.101 0.184
            -0.185 -0.136 0.184
            -0.135 -0.136 0.184
            -0.135 0.136 0.184
            -0.135 0.136 0.234
            -0.185 0.136 0.234
            -0.223 0.101 0.234
            -0.248 0.054 0.234
            -0.257 0 0.234
            -0.248 -0.054 0.234
            -0.223 -0.101 0.234
            -0.185 -0.136 0.234
            -0.135 -0.136 0.234
            -0.135 0.136 0.234
          ]
        }
        coordIndex [
          9, 8, 7, 6, 5, 4, 3, 2, 1, 0, -1, 10, 11, 12, 13, 14, 15, 16, 17, 18, 19, -1, 0, 1, 11, 10, -1, 1, 2, 12, 11, -1, 2, 3, 13, 12, -1, 3, 4, 14, 13, -1, 4, 5, 15, 14, -1, 5, 6, 16, 15, -1, 6, 7, 17, 16, -1, 7, 8, 18, 17, -1, 8, 9, 19, 18, -1
        ]
      }
    }
    Transform {
      translation -0.2147 0 0.0325
      rotation 0.5771968951617173 0.5771968951617173 0.577656895078166 -2.093935
      children [
        Shape {
          appearance PBRAppearance {
            baseColor 0.0037037 0.0037037 0.0037037
            roughness 0.3
            metalness 0
          }
          geometry Cylinder {
            height 0.024
            radius 0.0325
          }
        }
      ]
    }
    DistanceSensor {
      translation 0.164 0.027 0.209
      rotation 0 0 1 0.174203
      children [
        DEF SONAR Transform {
          rotation 0.577656895078166 0.5771968951617173 -0.5771968951617173 -2.093935
          children [
            Shape {
              appearance PBRAppearance {
                baseColor 1 1 0.0517103
                roughness 0.3
                metalness 0
              }
              geometry Cylinder {
                height 0.002
                radius 0.0175
              }
            }
          ]
        }
      ]
      name "ds0"
      lookupTable [
        0 1024 0
        0.2 1024 0.1
        0.4 0 0.1
      ]
      type "infra-red"
    }
    DistanceSensor {
      translation 0.147 0.077 0.209
      rotation 0.9352057350394192 0.25038992906003615 0.25038992906003615 1.637735
      children [
        USE SONAR
      ]
      name "ds1"
      lookupTable [
        0 1024 0
        0.2 1024 0.1
        0.4 0 0.1
      ]
      type "infra-red"
    }
    DistanceSensor {
      translation 0.116 0.118 0.209
      rotation 0.8349694730900802 0.38911822047269523 0.38911822047269523 1.750187
      children [
        USE SONAR
      ]
      name "ds2"
      lookupTable [
        0 1024 0
        0.2 1024 0.1
        0.4 0 0.1
      ]
      type "infra-red"
    }
    DistanceSensor {
      translation 0.071 0.136 0.209
      rotation 0.5779627730800116 0.5770437734408297 0.5770437734408297 2.093476
      children [
        USE SONAR
      ]
      name "ds3"
      lookupTable [
        0 1024 0
        0.2 1024 0.1
        0.4 0 0.1
      ]
      type "infra-red"
    }
    DistanceSensor {
      translation -0.16 0.136 0.209
      rotation -0.5767367732078247 -0.5776567728460501 -0.5776567728460501 -2.095315
      children [
        USE SONAR
      ]
      name "ds4"
      lookupTable [
        0 1024 0
        0.2 1024 0.1
        0.4 0 0.1
      ]
      type "infra-red"
    }
    DistanceSensor {
      translation -0.205 0.118 0.209
      rotation -0.31297577647997865 -0.6715825203713816 -0.6715825203713816 -2.534956
      children [
        USE SONAR
      ]
      name "ds5"
      lookupTable [
        0 1024 0
        0.2 1024 0.1
        0.4 0 0.1
      ]
      type "infra-red"
    }
    DistanceSensor {
      translation -0.236 0.077 0.209
      rotation -0.1860148912057814 -0.6947655936536081 -0.6947655936536081 -2.773767
      children [
        USE SONAR
      ]
      name "ds6"
      lookupTable [
        0 1024 0
        0.2 1024 0.1
        0.4 0 0.1
      ]
      type "infra-red"
    }
    DistanceSensor {
      translation -0.253 0.027 0.209
      rotation -0.06162897048037732 -0.7057626619471765 -0.7057626619471765 -3.01849
      children [
        USE SONAR
      ]
      name "ds7"
      lookupTable [
        0 1024 0
        0.2 1024 0.1
        0.4 0 0.1
      ]
      type "infra-red"
    }
    DistanceSensor {
      translation -0.253 -0.027 0.209
      rotation -0.06183904155773597 0.7057534742880195 0.7057534742880195 -3.018072
      children [
        USE SONAR
      ]
      name "ds8"
      lookupTable [
        0 1024 0
        0.2 1024 0.1
        0.4 0 0.1
      ]
      type "infra-red"
    }
    DistanceSensor {
      translation -0.236 -0.077 0.209
      rotation -0.1862280124472945 0.6947370464355309 0.6947370464355309 -2.773355
      children [
        USE SONAR
      ]
      name "ds9"
      lookupTable [
        0 1024 0
        0.2 1024 0.1
        0.4 0 0.1
      ]
      type "infra-red"
    }
    DistanceSensor {
      translation -0.205 -0.118 0.209
      rotation -0.31319385347479545 0.6715316858293465 0.6715316858293465 -2.534558
      children [
        USE SONAR
      ]
      name "ds10"
      lookupTable [
        0 1024 0
        0.2 1024 0.1
        0.4 0 0.1
      ]
      type "infra-red"
    }
    DistanceSensor {
      translation -0.16 -0.136 0.209
      rotation 0.5773502691896258 -0.5773502691896258 -0.5773502691896258 2.094395
      children [
        USE SONAR
      ]
      name "ds11"
      lookupTable [
        0 1024 0
        0.2 1024 0.1
        0.4 0 0.1
      ]
      type "infra-red"
    }
    DistanceSensor {
      translation 0.071 -0.136 0.209
      rotation 0.5773502691896258 -0.5773502691896258 -0.5773502691896258 2.094395
      children [
        USE SONAR
      ]
      name "ds12"
      lookupTable [
        0 1024 0
        0.2 1024 0.1
        0.4 0 0.1
      ]
      type "infra-red"
    }
    DistanceSensor {
      translation 0.116 -0.118 0.209
      rotation 0.8347739105773538 -0.38932795829441263 -0.38932795829441263 1.750417
      children [
        USE SONAR
      ]
      name "ds13"
      lookupTable [
        0 1024 0
        0.2 1024 0.1
        0.4 0 0.1
      ]
      type "infra-red"
    }
    DistanceSensor {
      translation 0.147 -0.077 0.209
      rotation 0.9350669359988784 -0.25064898284420567 -0.25064898284420567 1.637883
      children [
        USE SONAR
      ]
      name "ds14"
      lookupTable [
        0 1024 0
        0.2 1024 0.1
        0.4 0 0.1
      ]
      type "infra-red"
    }
    DistanceSensor {
      translation 0.164 -0.027 0.209
      rotation -0.9924098511524273 0.08695598695782032 0.08695598695782032 -1.578415
      children [
        USE SONAR
      ]
      name "ds15"
      lookupTable [
        0 1024 0
        0.2 1024 0.1
        0.4 0 0.1
      ]
      type "infra-red"
    }
  ]
  name "Pioneer 22"
  description "designed by Activmedia Robotics"
  boundingObject Transform {
    translation -0.0447 0 0.13
    rotation 0 0 1 -1.570796
    children [
      Cylinder {
        height 0.24
        radius 0.219
      }
    ]
  }
  controller ""
}
Robot {
  translation -6 6 0
  rotation -2.79442e-07 -3.25689e-08 -1 1.57079
  children [
    Lidar {
      translation 0 0 1.9
      rotation 0 1 0 0
      horizontalResolution 520
      fieldOfView 1.3
      verticalFieldOfView 0.7
      numberOfLayers 100
      maxRange 7
    }
    Group {
    }
    Shape {
      appearance PBRAppearance {
        baseColor 1 0 0
        roughness 0.3
        metalness 0
      }
      geometry IndexedFaceSet {
        coord Coordinate {
          point [
            -0.215 0.1 0.059
            -0.215 -0.1 0.059
            -0.185 -0.135 0.059
            0.095 -0.135 0.059
            0.11 -0.08 0.059
            0.11 0.08 0.059
            0.095 0.135 0.059
            -0.185 0.135 0.059
            -0.215 0.1 0.059
            -0.215 0.1 0.234
            -0.215 -0.1 0.234
            -0.185 -0.135 0.234
            0.095 -0.135 0.234
            0.11 -0.08 0.234
            0.11 0.08 0.234
            0.095 0.135 0.234
            -0.185 0.135 0.234
            -0.215 0.1 0.234
          ]
        }
        coordIndex [
          8, 7, 6, 5, 4, 3, 2, 1, 0, -1, 9, 10, 11, 12, 13, 14, 15, 16, 17, -1, 0, 1, 10, 9, -1, 1, 2, 11, 10, -1, 2, 3, 12, 11, -1, 3, 4, 13, 12, -1, 4, 5, 14, 13, -1, 5, 6, 15, 14, -1, 6, 7, 16, 15, -1, 7, 8, 17, 16, -1
        ]
      }
    }
    Shape {
      appearance PBRAppearance {
        baseColor 0.636415 0.655556 0.655556
        roughness 0.3
        metalness 0
      }
      geometry IndexedFaceSet {
        coord Coordinate {
          point [
            0.174 0 0.234, 0.166 0.056 0.234, 0.145 0.107 0.234, 0.112 0.155 0.234, 0.064 0.19 0.234, -0.074 0.19 0.234, -0.096 0.16 0.234, -0.151 0.16 0.234, -0.2 0.155 0.234, -0.236 0.107 0.234, -0.256 0.056 0.234, -0.264 0 0.234, -0.256 -0.056 0.234, -0.236 -0.107 0.234, -0.2 -0.155 0.234, -0.151 -0.16 0.234, -0.096 -0.16 0.234, -0.074 -0.19 0.234, 0.064 -0.19 0.234, 0.112 -0.155 0.234, 0.145 -0.107 0.234, 0.166 -0.056 0.234, 0.174 0 0.234, 0.174 0 0.245, 0.166 0.056 0.245, 0.145 0.107 0.245, 0.112 0.155 0.245, 0.064 0.19 0.245, -0.074 0.19 0.245, -0.096 0.16 0.245, -0.151 0.16 0.245, -0.2 0.155 0.245, -0.236 0.107 0.245, -0.256 0.056 0.245, -0.264 0 0.245, -0.256 -0.056 0.245, -0.236 -0.107 0.245, -0.2 -0.155 0.245, -0.151 -0.16 0.245, -0.096 -0.16 0.245, -0.074 -0.19 0.245, 0.064 -0.19 0.245, 0.112 -0.155 0.245, 0.145 -0.107 0.245, 0.166 -0.056 0.245, 0.174 0 0.245
          ]
        }
        coordIndex [
          22, 21, 20, 19, 18, 17, 16, 15, 14, 13, 12, 11, 10, 9, 8, 7, 6, 5, 4, 3, 2, 1, 0, -1, 23, 24, 25, 26, 27, 28, 29, 30, 31, 32, 33, 34, 35, 36, 37, 38, 39, 40, 41, 42, 43, 44, 45, -1, 0, 1, 24, 23, -1, 1, 2, 25, 24, -1, 2, 3, 26, 25, -1, 3, 4, 27, 26, -1, 4, 5, 28, 27, -1, 5, 6, 29, 28, -1, 6, 7, 30, 29, -1, 7, 8, 31, 30, -1, 8, 9, 32, 31, -1, 9, 10, 33, 32, -1, 10, 11, 34, 33, -1, 11, 12, 35, 34, -1, 12, 13, 36, 35, -1, 13, 14, 37, 36, -1, 14, 15, 38, 37, -1, 15, 16, 39, 38, -1, 16, 17, 40, 39, -1, 17, 18, 41, 40, -1, 18, 19, 42, 41, -1, 19, 20, 43, 42, -1, 20, 21, 44, 43, -1, 21, 22, 45, 44, -1
        ]
      }
    }
    HingeJoint {
      jointParameters HingeJointParameters {
        axis 0 1 0
        anchor 0 0 0.0825
      }
      device [
        RotationalMotor {
          name "left wheel motor"
        }
        PositionSensor {
          name "left wheel sensor"
        }
      ]
      endPoint Solid {
        translation -0.00863592 0.1603 0.0774581
        rotation 0.2526839701134262 -0.2526839701134262 -0.9339708895331986 1.639053
        children [
          DEF WHEEL Transform {
            rotation 0.577656895078166 0.5771968951617173 -0.5771968951617173 -2.093935
            children [
              Shape {
                appearance PBRAppearance {
                  baseColor 0.0037037 0.0037037 0.0037037
                  roughness 0.3
                  metalness 0
                }
                geometry Cylinder {
                  height 0.037
                  radius 0.0825
                }
              }
            ]
          }
        ]
        name "left wheel"
        boundingObject USE WHEEL
      }
    }
    HingeJoint {
      jointParameters HingeJointParameters {
        axis 0 1 0
        anchor 0 0 0.0825
      }
      device [
        RotationalMotor {
          name "right wheel motor"
        }
        PositionSensor {
          name "right wheel sensor"
        }
      ]
      endPoint Solid {
        translation 0 -0.1603 0.0825
        rotation 0.6879677669702216 -0.6879677669702216 -0.23108592172612774 2.687394
        children [
          USE WHEEL
        ]
        name "right wheel"
        boundingObject USE WHEEL
      }
    }
    Shape {
      appearance PBRAppearance {
        baseColor 1 0 0
        roughness 0.3
        metalness 0
      }
      geometry IndexedFaceSet {
        coord Coordinate {
          point [
            0.046 -0.136 0.184
            0.096 -0.136 0.184
            0.134 -0.101 0.184
            0.159 -0.054 0.184
            0.168 0 0.184
            0.159 0.054 0.184
            0.134 0.101 0.184
            0.096 0.136 0.184
            0.046 0.136 0.184
            0.043 -0.136 0.184
            0.046 -0.136 0.234
            0.096 -0.136 0.234
            0.134 -0.101 0.234
            0.159 -0.054 0.234
            0.168 0 0.234
            0.159 0.054 0.234
            0.134 0.101 0.234
            0.096 0.136 0.234
            0.046 0.136 0.234
            0.043 -0.136 0.234
          ]
        }
        coordIndex [
          9, 8, 7, 6, 5, 4, 3, 2, 1, 0, -1, 10, 11, 12, 13, 14, 15, 16, 17, 18, 19, -1, 0, 1, 11, 10, -1, 1, 2, 12, 11, -1, 2, 3, 13, 12, -1, 3, 4, 14, 13, -1, 4, 5, 15, 14, -1, 5, 6, 16, 15, -1, 6, 7, 17, 16, -1, 7, 8, 18, 17, -1, 8, 9, 19, 18, -1, 9, 0, 10, 19, -1
        ]
      }
    }
    Shape {
      appearance PBRAppearance {
        baseColor 1 0 0
        roughness 0.3
        metalness 0
      }
      geometry IndexedFaceSet {
        coord Coordinate {
          point [
            -0.135 0.136 0.184
            -0.185 0.136 0.184
            -0.223 0.101 0.184
            -0.248 0.054 0.184
            -0.257 0 0.184
            -0.248 -0.054 0.184
            -0.223 -0.101 0.184
            -0.185 -0.136 0.184
            -0.135 -0.136 0.184
            -0.135 0.136 0.184
            -0.135 0.136 0.234
            -0.185 0.136 0.234
            -0.223 0.101 0.234
            -0.248 0.054 0.234
            -0.257 0 0.234
            -0.248 -0.054 0.234
            -0.223 -0.101 0.234
            -0.185 -0.136 0.234
            -0.135 -0.136 0.234
            -0.135 0.136 0.234
          ]
        }
        coordIndex [
          9, 8, 7, 6, 5, 4, 3, 2, 1, 0, -1, 10, 11, 12, 13, 14, 15, 16, 17, 18, 19, -1, 0, 1, 11, 10, -1, 1, 2, 12, 11, -1, 2, 3, 13, 12, -1, 3, 4, 14, 13, -1, 4, 5, 15, 14, -1, 5, 6, 16, 15, -1, 6, 7, 17, 16, -1, 7, 8, 18, 17, -1, 8, 9, 19, 18, -1
        ]
      }
    }
    Transform {
      translation -0.2147 0 0.0325
      rotation 0.5771968951617173 0.5771968951617173 0.577656895078166 -2.093935
      children [
        Shape {
          appearance PBRAppearance {
            baseColor 0.0037037 0.0037037 0.0037037
            roughness 0.3
            metalness 0
          }
          geometry Cylinder {
            height 0.024
            radius 0.0325
          }
        }
      ]
    }
    DistanceSensor {
      translation 0.164 0.027 0.209
      rotation 0 0 1 0.174203
      children [
        DEF SONAR Transform {
          rotation 0.577656895078166 0.5771968951617173 -0.5771968951617173 -2.093935
          children [
            Shape {
              appearance PBRAppearance {
                baseColor 1 1 0.0517103
                roughness 0.3
                metalness 0
              }
              geometry Cylinder {
                height 0.002
                radius 0.0175
              }
            }
          ]
        }
      ]
      name "ds0"
      lookupTable [
        0 1024 0
        0.2 1024 0.1
        0.4 0 0.1
      ]
      type "infra-red"
    }
    DistanceSensor {
      translation 0.147 0.077 0.209
      rotation 0.9352057350394192 0.25038992906003615 0.25038992906003615 1.637735
      children [
        USE SONAR
      ]
      name "ds1"
      lookupTable [
        0 1024 0
        0.2 1024 0.1
        0.4 0 0.1
      ]
      type "infra-red"
    }
    DistanceSensor {
      translation 0.116 0.118 0.209
      rotation 0.8349694730900802 0.38911822047269523 0.38911822047269523 1.750187
      children [
        USE SONAR
      ]
      name "ds2"
      lookupTable [
        0 1024 0
        0.2 1024 0.1
        0.4 0 0.1
      ]
      type "infra-red"
    }
    DistanceSensor {
      translation 0.071 0.136 0.209
      rotation 0.5779627730800116 0.5770437734408297 0.5770437734408297 2.093476
      children [
        USE SONAR
      ]
      name "ds3"
      lookupTable [
        0 1024 0
        0.2 1024 0.1
        0.4 0 0.1
      ]
      type "infra-red"
    }
    DistanceSensor {
      translation -0.16 0.136 0.209
      rotation -0.5767367732078247 -0.5776567728460501 -0.5776567728460501 -2.095315
      children [
        USE SONAR
      ]
      name "ds4"
      lookupTable [
        0 1024 0
        0.2 1024 0.1
        0.4 0 0.1
      ]
      type "infra-red"
    }
    DistanceSensor {
      translation -0.205 0.118 0.209
      rotation -0.31297577647997865 -0.6715825203713816 -0.6715825203713816 -2.534956
      children [
        USE SONAR
      ]
      name "ds5"
      lookupTable [
        0 1024 0
        0.2 1024 0.1
        0.4 0 0.1
      ]
      type "infra-red"
    }
    DistanceSensor {
      translation -0.236 0.077 0.209
      rotation -0.1860148912057814 -0.6947655936536081 -0.6947655936536081 -2.773767
      children [
        USE SONAR
      ]
      name "ds6"
      lookupTable [
        0 1024 0
        0.2 1024 0.1
        0.4 0 0.1
      ]
      type "infra-red"
    }
    DistanceSensor {
      translation -0.253 0.027 0.209
      rotation -0.06162897048037732 -0.7057626619471765 -0.7057626619471765 -3.01849
      children [
        USE SONAR
      ]
      name "ds7"
      lookupTable [
        0 1024 0
        0.2 1024 0.1
        0.4 0 0.1
      ]
      type "infra-red"
    }
    DistanceSensor {
      translation -0.253 -0.027 0.209
      rotation -0.06183904155773597 0.7057534742880195 0.7057534742880195 -3.018072
      children [
        USE SONAR
      ]
      name "ds8"
      lookupTable [
        0 1024 0
        0.2 1024 0.1
        0.4 0 0.1
      ]
      type "infra-red"
    }
    DistanceSensor {
      translation -0.236 -0.077 0.209
      rotation -0.1862280124472945 0.6947370464355309 0.6947370464355309 -2.773355
      children [
        USE SONAR
      ]
      name "ds9"
      lookupTable [
        0 1024 0
        0.2 1024 0.1
        0.4 0 0.1
      ]
      type "infra-red"
    }
    DistanceSensor {
      translation -0.205 -0.118 0.209
      rotation -0.31319385347479545 0.6715316858293465 0.6715316858293465 -2.534558
      children [
        USE SONAR
      ]
      name "ds10"
      lookupTable [
        0 1024 0
        0.2 1024 0.1
        0.4 0 0.1
      ]
      type "infra-red"
    }
    DistanceSensor {
      translation -0.16 -0.136 0.209
      rotation 0.5773502691896258 -0.5773502691896258 -0.5773502691896258 2.094395
      children [
        USE SONAR
      ]
      name "ds11"
      lookupTable [
        0 1024 0
        0.2 1024 0.1
        0.4 0 0.1
      ]
      type "infra-red"
    }
    DistanceSensor {
      translation 0.071 -0.136 0.209
      rotation 0.5773502691896258 -0.5773502691896258 -0.5773502691896258 2.094395
      children [
        USE SONAR
      ]
      name "ds12"
      lookupTable [
        0 1024 0
        0.2 1024 0.1
        0.4 0 0.1
      ]
      type "infra-red"
    }
    DistanceSensor {
      translation 0.116 -0.118 0.209
      rotation 0.8347739105773538 -0.38932795829441263 -0.38932795829441263 1.750417
      children [
        USE SONAR
      ]
      name "ds13"
      lookupTable [
        0 1024 0
        0.2 1024 0.1
        0.4 0 0.1
      ]
      type "infra-red"
    }
    DistanceSensor {
      translation 0.147 -0.077 0.209
      rotation 0.9350669359988784 -0.25064898284420567 -0.25064898284420567 1.637883
      children [
        USE SONAR
      ]
      name "ds14"
      lookupTable [
        0 1024 0
        0.2 1024 0.1
        0.4 0 0.1
      ]
      type "infra-red"
    }
    DistanceSensor {
      translation 0.164 -0.027 0.209
      rotation -0.9924098511524273 0.08695598695782032 0.08695598695782032 -1.578415
      children [
        USE SONAR
      ]
      name "ds15"
      lookupTable [
        0 1024 0
        0.2 1024 0.1
        0.4 0 0.1
      ]
      type "infra-red"
    }
  ]
  name "Pioneer 33"
  description "designed by Activmedia Robotics"
  boundingObject Transform {
    translation -0.0447 0 0.13
    rotation 0 0 1 -1.570796
    children [
      Cylinder {
        height 0.24
        radius 0.219
      }
    ]
  }
  controller ""
}
Robot {
  translation 24.38 0.75012 8.73568e-08
  rotation 1.23436e-07 1.56005e-07 1 -3.1415853071795863
  children [
    Lidar {
      translation 0 0 5
      rotation 0 1 0 0
      horizontalResolution 520
      fieldOfView 1.3
      verticalFieldOfView 0.7
      numberOfLayers 10
      maxRange 3
    }
    Group {
    }
    Shape {
      appearance PBRAppearance {
        baseColor 1 0 0
        roughness 0.3
        metalness 0
      }
      geometry IndexedFaceSet {
        coord Coordinate {
          point [
            -0.215 0.1 0.059
            -0.215 -0.1 0.059
            -0.185 -0.135 0.059
            0.095 -0.135 0.059
            0.11 -0.08 0.059
            0.11 0.08 0.059
            0.095 0.135 0.059
            -0.185 0.135 0.059
            -0.215 0.1 0.059
            -0.215 0.1 0.234
            -0.215 -0.1 0.234
            -0.185 -0.135 0.234
            0.095 -0.135 0.234
            0.11 -0.08 0.234
            0.11 0.08 0.234
            0.095 0.135 0.234
            -0.185 0.135 0.234
            -0.215 0.1 0.234
          ]
        }
        coordIndex [
          8, 7, 6, 5, 4, 3, 2, 1, 0, -1, 9, 10, 11, 12, 13, 14, 15, 16, 17, -1, 0, 1, 10, 9, -1, 1, 2, 11, 10, -1, 2, 3, 12, 11, -1, 3, 4, 13, 12, -1, 4, 5, 14, 13, -1, 5, 6, 15, 14, -1, 6, 7, 16, 15, -1, 7, 8, 17, 16, -1
        ]
      }
    }
    Shape {
      appearance PBRAppearance {
        baseColor 0.636415 0.655556 0.655556
        roughness 0.3
        metalness 0
      }
      geometry IndexedFaceSet {
        coord Coordinate {
          point [
            0.174 0 0.234, 0.166 0.056 0.234, 0.145 0.107 0.234, 0.112 0.155 0.234, 0.064 0.19 0.234, -0.074 0.19 0.234, -0.096 0.16 0.234, -0.151 0.16 0.234, -0.2 0.155 0.234, -0.236 0.107 0.234, -0.256 0.056 0.234, -0.264 0 0.234, -0.256 -0.056 0.234, -0.236 -0.107 0.234, -0.2 -0.155 0.234, -0.151 -0.16 0.234, -0.096 -0.16 0.234, -0.074 -0.19 0.234, 0.064 -0.19 0.234, 0.112 -0.155 0.234, 0.145 -0.107 0.234, 0.166 -0.056 0.234, 0.174 0 0.234, 0.174 0 0.245, 0.166 0.056 0.245, 0.145 0.107 0.245, 0.112 0.155 0.245, 0.064 0.19 0.245, -0.074 0.19 0.245, -0.096 0.16 0.245, -0.151 0.16 0.245, -0.2 0.155 0.245, -0.236 0.107 0.245, -0.256 0.056 0.245, -0.264 0 0.245, -0.256 -0.056 0.245, -0.236 -0.107 0.245, -0.2 -0.155 0.245, -0.151 -0.16 0.245, -0.096 -0.16 0.245, -0.074 -0.19 0.245, 0.064 -0.19 0.245, 0.112 -0.155 0.245, 0.145 -0.107 0.245, 0.166 -0.056 0.245, 0.174 0 0.245
          ]
        }
        coordIndex [
          22, 21, 20, 19, 18, 17, 16, 15, 14, 13, 12, 11, 10, 9, 8, 7, 6, 5, 4, 3, 2, 1, 0, -1, 23, 24, 25, 26, 27, 28, 29, 30, 31, 32, 33, 34, 35, 36, 37, 38, 39, 40, 41, 42, 43, 44, 45, -1, 0, 1, 24, 23, -1, 1, 2, 25, 24, -1, 2, 3, 26, 25, -1, 3, 4, 27, 26, -1, 4, 5, 28, 27, -1, 5, 6, 29, 28, -1, 6, 7, 30, 29, -1, 7, 8, 31, 30, -1, 8, 9, 32, 31, -1, 9, 10, 33, 32, -1, 10, 11, 34, 33, -1, 11, 12, 35, 34, -1, 12, 13, 36, 35, -1, 13, 14, 37, 36, -1, 14, 15, 38, 37, -1, 15, 16, 39, 38, -1, 16, 17, 40, 39, -1, 17, 18, 41, 40, -1, 18, 19, 42, 41, -1, 19, 20, 43, 42, -1, 20, 21, 44, 43, -1, 21, 22, 45, 44, -1
        ]
      }
    }
    HingeJoint {
      jointParameters HingeJointParameters {
        axis 0 1 0
        anchor 0 0 0.0825
      }
      device [
        RotationalMotor {
          name "left wheel motor"
        }
        PositionSensor {
          name "left wheel sensor"
        }
      ]
      endPoint Solid {
        translation -0.00863592 0.1603 0.0774581
        rotation 0.2526839701134262 -0.2526839701134262 -0.9339708895331986 1.639053
        children [
          DEF WHEEL Transform {
            rotation 0.577656895078166 0.5771968951617173 -0.5771968951617173 -2.093935
            children [
              Shape {
                appearance PBRAppearance {
                  baseColor 0.0037037 0.0037037 0.0037037
                  roughness 0.3
                  metalness 0
                }
                geometry Cylinder {
                  height 0.037
                  radius 0.0825
                }
              }
            ]
          }
        ]
        name "left wheel"
        boundingObject USE WHEEL
      }
    }
    HingeJoint {
      jointParameters HingeJointParameters {
        axis 0 1 0
        anchor 0 0 0.0825
      }
      device [
        RotationalMotor {
          name "right wheel motor"
        }
        PositionSensor {
          name "right wheel sensor"
        }
      ]
      endPoint Solid {
        translation 0 -0.1603 0.0825
        rotation 0.6879677669702216 -0.6879677669702216 -0.23108592172612774 2.687394
        children [
          USE WHEEL
        ]
        name "right wheel"
        boundingObject USE WHEEL
      }
    }
    Shape {
      appearance PBRAppearance {
        baseColor 1 0 0
        roughness 0.3
        metalness 0
      }
      geometry IndexedFaceSet {
        coord Coordinate {
          point [
            0.046 -0.136 0.184
            0.096 -0.136 0.184
            0.134 -0.101 0.184
            0.159 -0.054 0.184
            0.168 0 0.184
            0.159 0.054 0.184
            0.134 0.101 0.184
            0.096 0.136 0.184
            0.046 0.136 0.184
            0.043 -0.136 0.184
            0.046 -0.136 0.234
            0.096 -0.136 0.234
            0.134 -0.101 0.234
            0.159 -0.054 0.234
            0.168 0 0.234
            0.159 0.054 0.234
            0.134 0.101 0.234
            0.096 0.136 0.234
            0.046 0.136 0.234
            0.043 -0.136 0.234
          ]
        }
        coordIndex [
          9, 8, 7, 6, 5, 4, 3, 2, 1, 0, -1, 10, 11, 12, 13, 14, 15, 16, 17, 18, 19, -1, 0, 1, 11, 10, -1, 1, 2, 12, 11, -1, 2, 3, 13, 12, -1, 3, 4, 14, 13, -1, 4, 5, 15, 14, -1, 5, 6, 16, 15, -1, 6, 7, 17, 16, -1, 7, 8, 18, 17, -1, 8, 9, 19, 18, -1, 9, 0, 10, 19, -1
        ]
      }
    }
    Shape {
      appearance PBRAppearance {
        baseColor 1 0 0
        roughness 0.3
        metalness 0
      }
      geometry IndexedFaceSet {
        coord Coordinate {
          point [
            -0.135 0.136 0.184
            -0.185 0.136 0.184
            -0.223 0.101 0.184
            -0.248 0.054 0.184
            -0.257 0 0.184
            -0.248 -0.054 0.184
            -0.223 -0.101 0.184
            -0.185 -0.136 0.184
            -0.135 -0.136 0.184
            -0.135 0.136 0.184
            -0.135 0.136 0.234
            -0.185 0.136 0.234
            -0.223 0.101 0.234
            -0.248 0.054 0.234
            -0.257 0 0.234
            -0.248 -0.054 0.234
            -0.223 -0.101 0.234
            -0.185 -0.136 0.234
            -0.135 -0.136 0.234
            -0.135 0.136 0.234
          ]
        }
        coordIndex [
          9, 8, 7, 6, 5, 4, 3, 2, 1, 0, -1, 10, 11, 12, 13, 14, 15, 16, 17, 18, 19, -1, 0, 1, 11, 10, -1, 1, 2, 12, 11, -1, 2, 3, 13, 12, -1, 3, 4, 14, 13, -1, 4, 5, 15, 14, -1, 5, 6, 16, 15, -1, 6, 7, 17, 16, -1, 7, 8, 18, 17, -1, 8, 9, 19, 18, -1
        ]
      }
    }
    Transform {
      translation -0.2147 0 0.0325
      rotation 0.5771968951617173 0.5771968951617173 0.577656895078166 -2.093935
      children [
        Shape {
          appearance PBRAppearance {
            baseColor 0.0037037 0.0037037 0.0037037
            roughness 0.3
            metalness 0
          }
          geometry Cylinder {
            height 0.024
            radius 0.0325
          }
        }
      ]
    }
    DistanceSensor {
      translation 0.164 0.027 0.209
      rotation 0 0 1 0.174203
      children [
        DEF SONAR Transform {
          rotation 0.577656895078166 0.5771968951617173 -0.5771968951617173 -2.093935
          children [
            Shape {
              appearance PBRAppearance {
                baseColor 1 1 0.0517103
                roughness 0.3
                metalness 0
              }
              geometry Cylinder {
                height 0.002
                radius 0.0175
              }
            }
          ]
        }
      ]
      name "ds0"
      lookupTable [
        0 1024 0
        0.2 1024 0.1
        0.4 0 0.1
      ]
      type "infra-red"
    }
    DistanceSensor {
      translation 0.147 0.077 0.209
      rotation 0.9352057350394192 0.25038992906003615 0.25038992906003615 1.637735
      children [
        USE SONAR
      ]
      name "ds1"
      lookupTable [
        0 1024 0
        0.2 1024 0.1
        0.4 0 0.1
      ]
      type "infra-red"
    }
    DistanceSensor {
      translation 0.116 0.118 0.209
      rotation 0.8349694730900802 0.38911822047269523 0.38911822047269523 1.750187
      children [
        USE SONAR
      ]
      name "ds2"
      lookupTable [
        0 1024 0
        0.2 1024 0.1
        0.4 0 0.1
      ]
      type "infra-red"
    }
    DistanceSensor {
      translation 0.071 0.136 0.209
      rotation 0.5779627730800116 0.5770437734408297 0.5770437734408297 2.093476
      children [
        USE SONAR
      ]
      name "ds3"
      lookupTable [
        0 1024 0
        0.2 1024 0.1
        0.4 0 0.1
      ]
      type "infra-red"
    }
    DistanceSensor {
      translation -0.16 0.136 0.209
      rotation -0.5767367732078247 -0.5776567728460501 -0.5776567728460501 -2.095315
      children [
        USE SONAR
      ]
      name "ds4"
      lookupTable [
        0 1024 0
        0.2 1024 0.1
        0.4 0 0.1
      ]
      type "infra-red"
    }
    DistanceSensor {
      translation -0.205 0.118 0.209
      rotation -0.31297577647997865 -0.6715825203713816 -0.6715825203713816 -2.534956
      children [
        USE SONAR
      ]
      name "ds5"
      lookupTable [
        0 1024 0
        0.2 1024 0.1
        0.4 0 0.1
      ]
      type "infra-red"
    }
    DistanceSensor {
      translation -0.236 0.077 0.209
      rotation -0.1860148912057814 -0.6947655936536081 -0.6947655936536081 -2.773767
      children [
        USE SONAR
      ]
      name "ds6"
      lookupTable [
        0 1024 0
        0.2 1024 0.1
        0.4 0 0.1
      ]
      type "infra-red"
    }
    DistanceSensor {
      translation -0.253 0.027 0.209
      rotation -0.06162897048037732 -0.7057626619471765 -0.7057626619471765 -3.01849
      children [
        USE SONAR
      ]
      name "ds7"
      lookupTable [
        0 1024 0
        0.2 1024 0.1
        0.4 0 0.1
      ]
      type "infra-red"
    }
    DistanceSensor {
      translation -0.253 -0.027 0.209
      rotation -0.06183904155773597 0.7057534742880195 0.7057534742880195 -3.018072
      children [
        USE SONAR
      ]
      name "ds8"
      lookupTable [
        0 1024 0
        0.2 1024 0.1
        0.4 0 0.1
      ]
      type "infra-red"
    }
    DistanceSensor {
      translation -0.236 -0.077 0.209
      rotation -0.1862280124472945 0.6947370464355309 0.6947370464355309 -2.773355
      children [
        USE SONAR
      ]
      name "ds9"
      lookupTable [
        0 1024 0
        0.2 1024 0.1
        0.4 0 0.1
      ]
      type "infra-red"
    }
    DistanceSensor {
      translation -0.205 -0.118 0.209
      rotation -0.31319385347479545 0.6715316858293465 0.6715316858293465 -2.534558
      children [
        USE SONAR
      ]
      name "ds10"
      lookupTable [
        0 1024 0
        0.2 1024 0.1
        0.4 0 0.1
      ]
      type "infra-red"
    }
    DistanceSensor {
      translation -0.16 -0.136 0.209
      rotation 0.5773502691896258 -0.5773502691896258 -0.5773502691896258 2.094395
      children [
        USE SONAR
      ]
      name "ds11"
      lookupTable [
        0 1024 0
        0.2 1024 0.1
        0.4 0 0.1
      ]
      type "infra-red"
    }
    DistanceSensor {
      translation 0.071 -0.136 0.209
      rotation 0.5773502691896258 -0.5773502691896258 -0.5773502691896258 2.094395
      children [
        USE SONAR
      ]
      name "ds12"
      lookupTable [
        0 1024 0
        0.2 1024 0.1
        0.4 0 0.1
      ]
      type "infra-red"
    }
    DistanceSensor {
      translation 0.116 -0.118 0.209
      rotation 0.8347739105773538 -0.38932795829441263 -0.38932795829441263 1.750417
      children [
        USE SONAR
      ]
      name "ds13"
      lookupTable [
        0 1024 0
        0.2 1024 0.1
        0.4 0 0.1
      ]
      type "infra-red"
    }
    DistanceSensor {
      translation 0.147 -0.077 0.209
      rotation 0.9350669359988784 -0.25064898284420567 -0.25064898284420567 1.637883
      children [
        USE SONAR
      ]
      name "ds14"
      lookupTable [
        0 1024 0
        0.2 1024 0.1
        0.4 0 0.1
      ]
      type "infra-red"
    }
    DistanceSensor {
      translation 0.164 -0.027 0.209
      rotation -0.9924098511524273 0.08695598695782032 0.08695598695782032 -1.578415
      children [
        USE SONAR
      ]
      name "ds15"
      lookupTable [
        0 1024 0
        0.2 1024 0.1
        0.4 0 0.1
      ]
      type "infra-red"
    }
  ]
  name "Pioneer 55"
  description "designed by Activmedia Robotics"
  boundingObject Transform {
    translation -0.0447 0 0.13
    rotation 0 0 1 -1.570796
    children [
      Cylinder {
        height 0.24
        radius 0.219
      }
    ]
  }
  controller ""
}
Robot {
  translation -6 -6 0
  rotation -2.79442e-07 -3.25689e-08 -1 -1.57079
  children [
    Lidar {
      translation 0 0 1.9
      rotation 0 1 0 0
      horizontalResolution 520
      fieldOfView 1.3
      verticalFieldOfView 0.7
      numberOfLayers 100
      maxRange 7
    }
    Group {
    }
    Shape {
      appearance PBRAppearance {
        baseColor 1 0 0
        roughness 0.3
        metalness 0
      }
      geometry IndexedFaceSet {
        coord Coordinate {
          point [
            -0.215 0.1 0.059
            -0.215 -0.1 0.059
            -0.185 -0.135 0.059
            0.095 -0.135 0.059
            0.11 -0.08 0.059
            0.11 0.08 0.059
            0.095 0.135 0.059
            -0.185 0.135 0.059
            -0.215 0.1 0.059
            -0.215 0.1 0.234
            -0.215 -0.1 0.234
            -0.185 -0.135 0.234
            0.095 -0.135 0.234
            0.11 -0.08 0.234
            0.11 0.08 0.234
            0.095 0.135 0.234
            -0.185 0.135 0.234
            -0.215 0.1 0.234
          ]
        }
        coordIndex [
          8, 7, 6, 5, 4, 3, 2, 1, 0, -1, 9, 10, 11, 12, 13, 14, 15, 16, 17, -1, 0, 1, 10, 9, -1, 1, 2, 11, 10, -1, 2, 3, 12, 11, -1, 3, 4, 13, 12, -1, 4, 5, 14, 13, -1, 5, 6, 15, 14, -1, 6, 7, 16, 15, -1, 7, 8, 17, 16, -1
        ]
      }
    }
    Shape {
      appearance PBRAppearance {
        baseColor 0.636415 0.655556 0.655556
        roughness 0.3
        metalness 0
      }
      geometry IndexedFaceSet {
        coord Coordinate {
          point [
            0.174 0 0.234, 0.166 0.056 0.234, 0.145 0.107 0.234, 0.112 0.155 0.234, 0.064 0.19 0.234, -0.074 0.19 0.234, -0.096 0.16 0.234, -0.151 0.16 0.234, -0.2 0.155 0.234, -0.236 0.107 0.234, -0.256 0.056 0.234, -0.264 0 0.234, -0.256 -0.056 0.234, -0.236 -0.107 0.234, -0.2 -0.155 0.234, -0.151 -0.16 0.234, -0.096 -0.16 0.234, -0.074 -0.19 0.234, 0.064 -0.19 0.234, 0.112 -0.155 0.234, 0.145 -0.107 0.234, 0.166 -0.056 0.234, 0.174 0 0.234, 0.174 0 0.245, 0.166 0.056 0.245, 0.145 0.107 0.245, 0.112 0.155 0.245, 0.064 0.19 0.245, -0.074 0.19 0.245, -0.096 0.16 0.245, -0.151 0.16 0.245, -0.2 0.155 0.245, -0.236 0.107 0.245, -0.256 0.056 0.245, -0.264 0 0.245, -0.256 -0.056 0.245, -0.236 -0.107 0.245, -0.2 -0.155 0.245, -0.151 -0.16 0.245, -0.096 -0.16 0.245, -0.074 -0.19 0.245, 0.064 -0.19 0.245, 0.112 -0.155 0.245, 0.145 -0.107 0.245, 0.166 -0.056 0.245, 0.174 0 0.245
          ]
        }
        coordIndex [
          22, 21, 20, 19, 18, 17, 16, 15, 14, 13, 12, 11, 10, 9, 8, 7, 6, 5, 4, 3, 2, 1, 0, -1, 23, 24, 25, 26, 27, 28, 29, 30, 31, 32, 33, 34, 35, 36, 37, 38, 39, 40, 41, 42, 43, 44, 45, -1, 0, 1, 24, 23, -1, 1, 2, 25, 24, -1, 2, 3, 26, 25, -1, 3, 4, 27, 26, -1, 4, 5, 28, 27, -1, 5, 6, 29, 28, -1, 6, 7, 30, 29, -1, 7, 8, 31, 30, -1, 8, 9, 32, 31, -1, 9, 10, 33, 32, -1, 10, 11, 34, 33, -1, 11, 12, 35, 34, -1, 12, 13, 36, 35, -1, 13, 14, 37, 36, -1, 14, 15, 38, 37, -1, 15, 16, 39, 38, -1, 16, 17, 40, 39, -1, 17, 18, 41, 40, -1, 18, 19, 42, 41, -1, 19, 20, 43, 42, -1, 20, 21, 44, 43, -1, 21, 22, 45, 44, -1
        ]
      }
    }
    HingeJoint {
      jointParameters HingeJointParameters {
        axis 0 1 0
        anchor 0 0 0.0825
      }
      device [
        RotationalMotor {
          name "left wheel motor"
        }
        PositionSensor {
          name "left wheel sensor"
        }
      ]
      endPoint Solid {
        translation -0.00863592 0.1603 0.0774581
        rotation 0.2526839701134262 -0.2526839701134262 -0.9339708895331986 1.639053
        children [
          DEF WHEEL Transform {
            rotation 0.577656895078166 0.5771968951617173 -0.5771968951617173 -2.093935
            children [
              Shape {
                appearance PBRAppearance {
                  baseColor 0.0037037 0.0037037 0.0037037
                  roughness 0.3
                  metalness 0
                }
                geometry Cylinder {
                  height 0.037
                  radius 0.0825
                }
              }
            ]
          }
        ]
        name "left wheel"
        boundingObject USE WHEEL
      }
    }
    HingeJoint {
      jointParameters HingeJointParameters {
        axis 0 1 0
        anchor 0 0 0.0825
      }
      device [
        RotationalMotor {
          name "right wheel motor"
        }
        PositionSensor {
          name "right wheel sensor"
        }
      ]
      endPoint Solid {
        translation 0 -0.1603 0.0825
        rotation 0.6879677669702216 -0.6879677669702216 -0.23108592172612774 2.687394
        children [
          USE WHEEL
        ]
        name "right wheel"
        boundingObject USE WHEEL
      }
    }
    Shape {
      appearance PBRAppearance {
        baseColor 1 0 0
        roughness 0.3
        metalness 0
      }
      geometry IndexedFaceSet {
        coord Coordinate {
          point [
            0.046 -0.136 0.184
            0.096 -0.136 0.184
            0.134 -0.101 0.184
            0.159 -0.054 0.184
            0.168 0 0.184
            0.159 0.054 0.184
            0.134 0.101 0.184
            0.096 0.136 0.184
            0.046 0.136 0.184
            0.043 -0.136 0.184
            0.046 -0.136 0.234
            0.096 -0.136 0.234
            0.134 -0.101 0.234
            0.159 -0.054 0.234
            0.168 0 0.234
            0.159 0.054 0.234
            0.134 0.101 0.234
            0.096 0.136 0.234
            0.046 0.136 0.234
            0.043 -0.136 0.234
          ]
        }
        coordIndex [
          9, 8, 7, 6, 5, 4, 3, 2, 1, 0, -1, 10, 11, 12, 13, 14, 15, 16, 17, 18, 19, -1, 0, 1, 11, 10, -1, 1, 2, 12, 11, -1, 2, 3, 13, 12, -1, 3, 4, 14, 13, -1, 4, 5, 15, 14, -1, 5, 6, 16, 15, -1, 6, 7, 17, 16, -1, 7, 8, 18, 17, -1, 8, 9, 19, 18, -1, 9, 0, 10, 19, -1
        ]
      }
    }
    Shape {
      appearance PBRAppearance {
        baseColor 1 0 0
        roughness 0.3
        metalness 0
      }
      geometry IndexedFaceSet {
        coord Coordinate {
          point [
            -0.135 0.136 0.184
            -0.185 0.136 0.184
            -0.223 0.101 0.184
            -0.248 0.054 0.184
            -0.257 0 0.184
            -0.248 -0.054 0.184
            -0.223 -0.101 0.184
            -0.185 -0.136 0.184
            -0.135 -0.136 0.184
            -0.135 0.136 0.184
            -0.135 0.136 0.234
            -0.185 0.136 0.234
            -0.223 0.101 0.234
            -0.248 0.054 0.234
            -0.257 0 0.234
            -0.248 -0.054 0.234
            -0.223 -0.101 0.234
            -0.185 -0.136 0.234
            -0.135 -0.136 0.234
            -0.135 0.136 0.234
          ]
        }
        coordIndex [
          9, 8, 7, 6, 5, 4, 3, 2, 1, 0, -1, 10, 11, 12, 13, 14, 15, 16, 17, 18, 19, -1, 0, 1, 11, 10, -1, 1, 2, 12, 11, -1, 2, 3, 13, 12, -1, 3, 4, 14, 13, -1, 4, 5, 15, 14, -1, 5, 6, 16, 15, -1, 6, 7, 17, 16, -1, 7, 8, 18, 17, -1, 8, 9, 19, 18, -1
        ]
      }
    }
    Transform {
      translation -0.2147 0 0.0325
      rotation 0.5771968951617173 0.5771968951617173 0.577656895078166 -2.093935
      children [
        Shape {
          appearance PBRAppearance {
            baseColor 0.0037037 0.0037037 0.0037037
            roughness 0.3
            metalness 0
          }
          geometry Cylinder {
            height 0.024
            radius 0.0325
          }
        }
      ]
    }
    DistanceSensor {
      translation 0.164 0.027 0.209
      rotation 0 0 1 0.174203
      children [
        DEF SONAR Transform {
          rotation 0.577656895078166 0.5771968951617173 -0.5771968951617173 -2.093935
          children [
            Shape {
              appearance PBRAppearance {
                baseColor 1 1 0.0517103
                roughness 0.3
                metalness 0
              }
              geometry Cylinder {
                height 0.002
                radius 0.0175
              }
            }
          ]
        }
      ]
      name "ds0"
      lookupTable [
        0 1024 0
        0.2 1024 0.1
        0.4 0 0.1
      ]
      type "infra-red"
    }
    DistanceSensor {
      translation 0.147 0.077 0.209
      rotation 0.9352057350394192 0.25038992906003615 0.25038992906003615 1.637735
      children [
        USE SONAR
      ]
      name "ds1"
      lookupTable [
        0 1024 0
        0.2 1024 0.1
        0.4 0 0.1
      ]
      type "infra-red"
    }
    DistanceSensor {
      translation 0.116 0.118 0.209
      rotation 0.8349694730900802 0.38911822047269523 0.38911822047269523 1.750187
      children [
        USE SONAR
      ]
      name "ds2"
      lookupTable [
        0 1024 0
        0.2 1024 0.1
        0.4 0 0.1
      ]
      type "infra-red"
    }
    DistanceSensor {
      translation 0.071 0.136 0.209
      rotation 0.5779627730800116 0.5770437734408297 0.5770437734408297 2.093476
      children [
        USE SONAR
      ]
      name "ds3"
      lookupTable [
        0 1024 0
        0.2 1024 0.1
        0.4 0 0.1
      ]
      type "infra-red"
    }
    DistanceSensor {
      translation -0.16 0.136 0.209
      rotation -0.5767367732078247 -0.5776567728460501 -0.5776567728460501 -2.095315
      children [
        USE SONAR
      ]
      name "ds4"
      lookupTable [
        0 1024 0
        0.2 1024 0.1
        0.4 0 0.1
      ]
      type "infra-red"
    }
    DistanceSensor {
      translation -0.205 0.118 0.209
      rotation -0.31297577647997865 -0.6715825203713816 -0.6715825203713816 -2.534956
      children [
        USE SONAR
      ]
      name "ds5"
      lookupTable [
        0 1024 0
        0.2 1024 0.1
        0.4 0 0.1
      ]
      type "infra-red"
    }
    DistanceSensor {
      translation -0.236 0.077 0.209
      rotation -0.1860148912057814 -0.6947655936536081 -0.6947655936536081 -2.773767
      children [
        USE SONAR
      ]
      name "ds6"
      lookupTable [
        0 1024 0
        0.2 1024 0.1
        0.4 0 0.1
      ]
      type "infra-red"
    }
    DistanceSensor {
      translation -0.253 0.027 0.209
      rotation -0.06162897048037732 -0.7057626619471765 -0.7057626619471765 -3.01849
      children [
        USE SONAR
      ]
      name "ds7"
      lookupTable [
        0 1024 0
        0.2 1024 0.1
        0.4 0 0.1
      ]
      type "infra-red"
    }
    DistanceSensor {
      translation -0.253 -0.027 0.209
      rotation -0.06183904155773597 0.7057534742880195 0.7057534742880195 -3.018072
      children [
        USE SONAR
      ]
      name "ds8"
      lookupTable [
        0 1024 0
        0.2 1024 0.1
        0.4 0 0.1
      ]
      type "infra-red"
    }
    DistanceSensor {
      translation -0.236 -0.077 0.209
      rotation -0.1862280124472945 0.6947370464355309 0.6947370464355309 -2.773355
      children [
        USE SONAR
      ]
      name "ds9"
      lookupTable [
        0 1024 0
        0.2 1024 0.1
        0.4 0 0.1
      ]
      type "infra-red"
    }
    DistanceSensor {
      translation -0.205 -0.118 0.209
      rotation -0.31319385347479545 0.6715316858293465 0.6715316858293465 -2.534558
      children [
        USE SONAR
      ]
      name "ds10"
      lookupTable [
        0 1024 0
        0.2 1024 0.1
        0.4 0 0.1
      ]
      type "infra-red"
    }
    DistanceSensor {
      translation -0.16 -0.136 0.209
      rotation 0.5773502691896258 -0.5773502691896258 -0.5773502691896258 2.094395
      children [
        USE SONAR
      ]
      name "ds11"
      lookupTable [
        0 1024 0
        0.2 1024 0.1
        0.4 0 0.1
      ]
      type "infra-red"
    }
    DistanceSensor {
      translation 0.071 -0.136 0.209
      rotation 0.5773502691896258 -0.5773502691896258 -0.5773502691896258 2.094395
      children [
        USE SONAR
      ]
      name "ds12"
      lookupTable [
        0 1024 0
        0.2 1024 0.1
        0.4 0 0.1
      ]
      type "infra-red"
    }
    DistanceSensor {
      translation 0.116 -0.118 0.209
      rotation 0.8347739105773538 -0.38932795829441263 -0.38932795829441263 1.750417
      children [
        USE SONAR
      ]
      name "ds13"
      lookupTable [
        0 1024 0
        0.2 1024 0.1
        0.4 0 0.1
      ]
      type "infra-red"
    }
    DistanceSensor {
      translation 0.147 -0.077 0.209
      rotation 0.9350669359988784 -0.25064898284420567 -0.25064898284420567 1.637883
      children [
        USE SONAR
      ]
      name "ds14"
      lookupTable [
        0 1024 0
        0.2 1024 0.1
        0.4 0 0.1
      ]
      type "infra-red"
    }
    DistanceSensor {
      translation 0.164 -0.027 0.209
      rotation -0.9924098511524273 0.08695598695782032 0.08695598695782032 -1.578415
      children [
        USE SONAR
      ]
      name "ds15"
      lookupTable [
        0 1024 0
        0.2 1024 0.1
        0.4 0 0.1
      ]
      type "infra-red"
    }
  ]
  name "Pioneer 44"
  description "designed by Activmedia Robotics"
  boundingObject Transform {
    translation -0.0447 0 0.13
    rotation 0 0 1 -1.570796
    children [
      Cylinder {
        height 0.24
        radius 0.219
      }
    ]
  }
  controller "pioneer_4_cnt"
}
Rock17cm {
  translation 0 9.42 0
}
Rock17cm {
  translation 0.63 9.42 0
  name "rock 17 cm(1)"
}
Rock17cm {
  translation 1.27 9.42 0
  name "rock 17 cm(2)"
}
Fountain {
  translation 26.87 8.71 0
}
Bench {
  translation 25.2182 5.4984 0
  rotation 0 0 1 0.785398
}
SimpleBench {
  translation 30.11 9.71 0
}
SimpleBench {
  translation 30.11 7.88 0
  name "simple bench(1)"
}
SimpleBench {
  translation 30.11 6.03 0
  name "simple bench(2)"
}
OldBench {
  translation 24.3345 10.39 0
  rotation 0 0 1 -0.523595307179586
}
RobocupSoccerBall {
  translation -0.10990188524489684 8.52 0.16987585278283343
  rotation 0 -1 0 1.5700275835278934
}
PicketFenceWithDoor {
  translation 22.91 15.64 0
  rotation 0 0 1 -1.5707953071795862
}
PicketFenceWithDoor {
  translation 27.39 15.64 0
  rotation 0 0 1 -1.5707953071795862
  name "picket fence with door(5)"
}
PicketFenceWithDoor {
  translation -7.31 -9.91 0.07
  rotation 0 0 1 -1.5707953071795862
  name "picket fence with door(7)"
}
PicketFenceWithDoor {
  translation -2.75 -9.75 0.07
  rotation 0 0 1 -1.5707953071795862
  name "picket fence with door(8)"
}
PicketFenceWithDoor {
  translation 1.89 -9.75 0.07
  rotation 0 0 1 -1.5707953071795862
  name "picket fence with door(9)"
}
TableWithUmbrella {
  translation -0.04 -6.44 0
}
PicketFenceWithDoor {
  translation 18.49 15.64 0
  rotation 0 0 1 -1.5707953071795862
  name "picket fence with door(1)"
}
PicketFenceWithDoor {
  translation 13.97 15.64 0
  rotation 0 0 1 -1.5707953071795862
  name "picket fence with door(2)"
}
PicketFenceWithDoor {
  translation 9.33 15.64 0
  rotation 0 0 1 -1.5707953071795862
  name "picket fence with door(3)"
}
PicketFenceWithDoor {
  translation 4.73 15.64 0
  rotation 0 0 1 -1.5707953071795862
  name "picket fence with door(4)"
}
Pedestrian {
  translation 7.79 8.17 1.27
}
Pedestrian {
  translation 8.61 7.95 1.37
  rotation 0 0 1 3.14159
  name "pedestrian(1)"
}
Pedestrian {
  translation 34.3 3.32 1.47
  name "pedestrian(2)"
  shirtColor 0.937255 0.160784 0.160784
}
Floor {
  translation 2 0 0.1
  appearance Parquetry {
    type "chequered"
    colorOverride 0.68333 0.829007 1
  }
}
Armchair {
  translation -1.09119 3.25 0
  rotation 0 0 1 -0.523595307179586
}
Table {
  translation 4.26911 2.74712 0
  rotation 0 0 1 3.14159
}
RoundTable {
  translation 4.83 -2.65 0
}
DogHouse {
  translation 1.94 11.65 0
  rotation 0 0 1 -1.5707953071795862
}
Pergolas {
  translation 1.17 12.04 0
}
Pergolas {
  translation 21.3 -12.41 0
  name "pergola(1)"
}
Pergolas {
  translation 16.55 -6.59 0
  name "pergola(2)"
}
Pergolas {
  translation 11.93 -6.59 0
  name "pergola(3)"
}
TeslaModel3 {
  hidden position_0_0 -1.8678597992307798e-05
  hidden position2_0_0 -0.004570868672291304
  hidden position_0_1 1.8678639396399836e-05
  hidden position2_0_1 -0.004570890253743962
  hidden position_0_2 -1.9820602713093555e-05
  hidden position_0_3 -1.9820101519508223e-05
  hidden linearVelocity_0 0.0002685882848444598 -0.00015246274253811806 0.0009592098960265067
  hidden angularVelocity_0 4.6862601239511024e-05 8.257521278139517e-05 -9.260069719437685e-11
  hidden translation_1 0 0 0
  hidden rotation_1 0.0018544430350284238 -0.9999966021890714 -0.0018321166289283857 1.5707993738081438
  hidden linearVelocity_1 0.00025080281157998345 -0.00017238634671398162 0.0013804230543440872
  hidden angularVelocity_1 0.0004080897193084221 0.0007362708512582074 -1.9630588535956802e-07
  hidden translation_2 0 0 0
  hidden rotation_2 -0.0018544554819467554 -0.9999966021432779 0.0018321290250607508 1.570799373853693
  hidden linearVelocity_2 0.0002765788917143666 -0.000126978369922631 0.0013804356746374453
  hidden angularVelocity_2 0.0004229863338566579 0.0007278142846234914 1.9627232429400716e-07
  hidden translation_3 0 0 0
  hidden rotation_3 7.340121092298453e-06 -0.9999999999461228 -7.34011869358479e-06 1.570796000053876
  hidden linearVelocity_3 0.0006544026623071266 -0.00040659936927583756 0.001675787787610716
  hidden angularVelocity_3 0.001291866284173117 0.002295901553075958 1.7324370394278032e-05
  hidden translation_4 0 0 0
  hidden rotation_4 -7.339842998061749e-06 -0.9999999999461268 7.339840599438816e-06 1.570796000053872
  hidden linearVelocity_4 0.0006845647665958063 -0.0003534691282156083 0.0016758002690395635
  hidden angularVelocity_4 0.0013091276143538115 0.002286111847087482 -1.7324101146354203e-05
  translation -7.305935920128115 11.789454839392558 0.15471331542503805
  rotation -0.006245157230191604 -0.02365301649335803 -0.9997007216271953 0.5164471070932434
  name "vehicle(3)"
}
RangeRoverSportSVR {
  hidden position_0_0 9.343374187413446e-06
  hidden position2_0_0 0.00028109635062429137
  hidden position_0_1 9.372488744872088e-06
  hidden position2_0_1 0.00046430434298894336
  hidden position_0_2 -0.00034991248134103893
  hidden position_0_3 -0.0006907686632997015
  hidden linearVelocity_0 -3.6052010547501064e-05 2.9281367419665723e-05 -0.007815515337526304
  hidden angularVelocity_0 -1.919746405256491e-05 4.034729431546979e-06 -5.623733154326146e-07
  hidden translation_1 0 0 0
  hidden rotation_1 -0.9994483890831044 4.669102265859759e-06 -0.03321020230873509 0.0002813409478662514
  hidden linearVelocity_1 1.8308625949572457e-05 -2.8643606535205407e-06 -0.0064265350217687645
  hidden angularVelocity_1 -2.4999940345112184e-05 -6.957309105117781e-06 -5.690663957928659e-07
  hidden translation_2 0 0 0
  hidden rotation_2 0.9997964022266191 -4.685298142447782e-06 -0.02017805919201499 0.0004644883194144326
  hidden linearVelocity_2 1.8920506432429116e-05 -3.1819515404793323e-06 -0.006401041215888575
  hidden angularVelocity_2 -2.5145227009874796e-05 -7.237433083354459e-06 -5.690771379672541e-07
  hidden translation_3 0 0 0
  hidden rotation_3 1 0 0 0.00034971705506333945
  hidden linearVelocity_3 4.090481473235354e-06 3.5707778856907028e-06 -0.006465999881339326
  hidden angularVelocity_3 -2.430406556191627e-05 -3.4329180063407445e-06 -5.693106383454193e-07
  hidden translation_4 0 0 0
  hidden rotation_4 -1 0 0 0.0006905732366052576
  hidden linearVelocity_4 4.705579395165456e-06 3.2514819227995178e-06 -0.006440505647782642
  hidden angularVelocity_4 -2.4442907651747924e-05 -3.7006316475236924e-06 -5.693221082811822e-07
  translation -8.21225935802968 9.552719991318305 0.08840854773373621
  rotation 0.005550686338245256 0.022619869676287655 -0.9997287288944947 0.4789872773631866
  name "vehicle(2)"
}
PottedTree {
  translation 0 11.99 0.2
}
SuburbanHouse {
  translation 42.08 -5.23556e-05 0
  rotation 0 0 1 3.14159
}
Swing {
  translation 11.56 6.59 0
}
Slide {
  translation 12.55 2.11 0
  rotation 0 0 1 3.14159
}
Oak {
  translation 17.63 10.83 0
}
Oak {
  translation 17.63 9.06 0
  name "oak tree(1)"
}
Oak {
  translation 14.85 11.43 0
  name "oak tree(3)"
}
Oak {
  translation 14.85 10.17 0
  name "oak tree(4)"
}
Oak {
  translation 14.85 8.26 0
  name "oak tree(5)"
}
Oak {
  translation 14.85 8.26 0
  name "oak tree(6)"
}
Oak {
  translation 17.63 7.4 0
  name "oak tree(2)"
}
Forest {
  translation 13.6 38.79 0
}
SimpleTwoFloorsHouse {
  translation -20.4 6.39 0
  rotation 0 0 1 3.14159
}
Oak {
  translation 46.73 0 0
  name "oak tree(7)"
}
PalmTree {
  translation 48.78 0 0
}
PalmTree {
  translation 48.78 1.76 0
  name "palm tree(1)"
}
PalmTree {
  translation 48.78 3.92 0
  name "palm tree(2)"
}
PalmTree {
  translation 48.78 5.79 0
  name "palm tree(3)"
}
PalmTree {
  translation 46.32 10.31 0
  name "palm tree(19)"
}
PalmTree {
  translation 46.32 6.04 0
  name "palm tree(20)"
}
PalmTree {
  translation 46.32 2.55 0
  name "palm tree(21)"
}
PalmTree {
  translation 46.32 -1.96 0
  name "palm tree(22)"
}
PalmTree {
  translation 25.7 -14.15 0
  name "palm tree(23)"
}
PalmTree {
  translation 29.37 -14.15 0
  name "palm tree(24)"
}
PalmTree {
  translation 31.8 -14.15 0
  name "palm tree(25)"
}
PalmTree {
  translation 31.8 -10.07 0
  name "palm tree(26)"
}
PalmTree {
  translation 31.8 -18.55 0
  name "palm tree(27)"
}
PalmTree {
  translation 35.46 -12.36 0
  name "palm tree(28)"
}
PalmTree {
  translation 35.46 -8.46 0
  name "palm tree(29)"
}
PalmTree {
  translation 25.7 -8.46 0
  name "palm tree(30)"
}
PalmTree {
  translation 28.16 -18.21 0
  name "palm tree(31)"
}
PalmTree {
  translation 23.66 -18.21 0
  name "palm tree(32)"
}
PalmTree {
  translation 40.88 -13.34 0
  name "palm tree(33)"
}
PalmTree {
  translation 40.88 -9.33 0
  name "palm tree(34)"
}
PalmTree {
  translation 43.93 -9.33 0
  name "palm tree(35)"
}
PalmTree {
  translation 46.89 -12.78 0
  name "palm tree(36)"
}
PalmTree {
  translation 20.07 13.19 0
  name "palm tree(37)"
}
PalmTree {
  translation 20.07 6.58 0
  name "palm tree(38)"
}
PalmTree {
  translation 14.3 1.5 0
  name "palm tree(39)"
}
PalmTree {
  translation 14.3 12.24 0
  name "palm tree(40)"
}
PalmTree {
  translation 9.66 12.24 0
  name "palm tree(41)"
}
PalmTree {
  translation -11.86 12.24 0
  name "palm tree(42)"
}
PalmTree {
  translation -7.97 13.98 0
  name "palm tree(43)"
}
PalmTree {
  translation -7.97 23.39 0
  name "palm tree(44)"
}
PalmTree {
  translation -4.28 -6.54 0
  name "palm tree(45)"
}
PalmTree {
  translation 48.78 7.24 0
  name "palm tree(4)"
}
PalmTree {
  translation 50.9 7.24 0
  name "palm tree(5)"
}
PalmTree {
  translation 50.9 5.03 0
  name "palm tree(6)"
}
PalmTree {
  translation 50.9 3.01 0
  name "palm tree(7)"
}
PalmTree {
  translation 50.9 -0.37 0
  name "palm tree(8)"
}
PalmTree {
  translation 50.9 -2.93 0
  name "palm tree(9)"
}
PalmTree {
  translation 50.9 -5.52 0
  name "palm tree(10)"
}
PalmTree {
  translation 50.9 -7.68 0
  name "palm tree(11)"
}
PalmTree {
  translation 46.87 -7.68 0
  name "palm tree(12)"
}
PalmTree {
  translation 46.87 -3.63 0
  name "palm tree(13)"
}
PalmTree {
  translation 53.5 -3.63 0
  name "palm tree(14)"
}
PalmTree {
  translation 53.5 -0.46 0
  name "palm tree(15)"
}
PalmTree {
  translation 53.5 4.93 0
  name "palm tree(16)"
}
PalmTree {
  translation 53.5 7.12 0
  name "palm tree(17)"
}
PalmTree {
  translation 53.5 -8.4 0
  name "palm tree(18)"
}
BigSassafras {
  translation -13.17 -3.62 0
}
BigSassafras {
  translation -5.75 -10.73 0
  name "sassafras tree(1)"
}
BigSassafras {
  translation -10.4 -7.72 0
  name "sassafras tree(2)"
}
BigSassafras {
  translation -13.17 -11.86 0
  name "sassafras tree(3)"
}
BigSassafras {
  translation -20.18 -6.92 0
  name "sassafras tree(4)"
}
BigSassafras {
  translation -7.4 -7.72 0
  name "sassafras tree(5)"
}
Forest {
  translation -8.65753 27.522 0
  rotation 0 0 1 1.0472
}
Forest {
  translation 34.7088 29.1348 0
  rotation 0 0 1 1.0472
}
Forest {
  translation 21.9056 -35.5608 0
  rotation 0 0 1 1.0472
}
Forest {
  translation 42.7614 -29.2751 0
  rotation 0 0 -1 -0.5236053071795865
}
Forest {
  translation 3.47842 -22.6239 0
  rotation 0 0 1 2.0944
}
Forest {
  translation -4.29016 -36.5329 0
  rotation 0 0 1 1.0472
}
Forest {
  translation -21.2382 -26.7479 0
  rotation 0 0 1 1.0472
}
Forest {
  translation -26.7332 -36.2657 0
  rotation 0 0 1 1.0472
}
Forest {
  translation -34.2203 -17.6657 0
  rotation 0 0 1 1.5708
}
Forest {
  translation -34.2203 24.1543 0
  rotation 0 0 1 1.5708
}
BigSassafras {
  translation -13.17 -7.72 0
  name "sassafras tree(6)"
}
Forest {
  translation -27.86 39.28 0
}
Forest {
  translation 42.4688 29.8042 0
  rotation 0 0 1 0.523599
}
Forest {
  translation 35.4639 39.0516 0
  rotation 0 0 1 -5.307179586466759e-06
}
Forest {
  translation -28.2661 39.0516 0
  rotation 0 0 1 -5.307179586466759e-06
}
Forest {
  translation 35.8102 -28.9698 0
  rotation 0 0 1 0.785398
}
ToyotaPrius {
  hidden position_0_0 -8.001967075390982e-10
  hidden position2_0_0 4.245633074184402e-06
  hidden position_0_1 -6.626530535015185e-10
  hidden position2_0_1 1.7954534377853372e-06
  hidden position_0_2 -0.007936272110214514
  hidden position_0_3 -0.008029270116132874
  hidden linearVelocity_0 -0.000580989899488007 4.192744436754499e-06 -0.006493773396108045
  hidden angularVelocity_0 -8.25352253007092e-06 -0.0025043095398584033 9.319706678348506e-06
  hidden translation_1 0 0 0
  hidden rotation_1 -0.9999974968030692 -4.6815836414586635e-09 -0.0022374958314566587 4.913950213056646e-06
  hidden linearVelocity_1 -0.0007304991473320441 8.973998858563024e-07 -0.00241943467568848
  hidden angularVelocity_1 -2.0148367215588853e-05 -0.0024453539936814886 8.403904268154135e-06
  hidden translation_2 0 0 0
  hidden rotation_2 0.9999883610775088 3.591231244304288e-09 -0.004824697868040176 2.3125142734727175e-06
  hidden linearVelocity_2 -0.0007368600496236258 9.029664524270176e-07 -0.002298032094745307
  hidden angularVelocity_2 -2.0148857988814894e-05 -0.0024381793549614447 8.40296613345713e-06
  hidden translation_3 0 0 0
  hidden rotation_3 1 0 0 0.006316576862259337
  hidden linearVelocity_3 -0.0003120984421738342 7.191556389682956e-06 -0.007571999985471772
  hidden angularVelocity_3 -1.1371085274602765e-05 -0.0009844908648739363 8.011450242412535e-06
  hidden translation_4 0 0 0
  hidden rotation_4 -1 0 0 0.0064559368126184125
  hidden linearVelocity_4 -0.0002991795579835077 7.200319505649489e-06 -0.007453610664561339
  hidden angularVelocity_4 -1.1381592760793444e-05 -0.0009437493473179424 8.00757717202188e-06
  translation 29.360663165392715 -5.099925155549473 0.12448674063602874
  rotation -0.007725216870160653 -0.9999697268413086 -0.000930819653472322 0.016604240043421988
}
ToyotaPrius {
  hidden position_0_0 -8.001779952832187e-10
  hidden position2_0_0 4.24563310977326e-06
  hidden position_0_1 -6.626326345039163e-10
  hidden position2_0_1 1.7954533721050844e-06
  hidden position_0_2 -0.007936271945210833
  hidden position_0_3 -0.008029270180576746
  hidden linearVelocity_0 -0.0005809899131385351 4.190822612697949e-06 -0.006493773397205875
  hidden angularVelocity_0 -8.245237858943438e-06 -0.002504309567719007 9.319706759850312e-06
  hidden translation_1 0 0 0
  hidden rotation_1 -0.999995300349811 -5.7194904795734355e-09 -0.0030658242434147194 5.179434427486999e-06
  hidden linearVelocity_1 -0.0007304991504800904 8.949832120364948e-07 -0.0024194346766406214
  hidden angularVelocity_1 -2.0140277717958067e-05 -0.0024453540608487595 8.403904344135038e-06
  hidden translation_2 0 0 0
  hidden rotation_2 0.9999799490611782 3.727523896967412e-09 -0.006332572589683436 2.552234419108402e-06
  hidden linearVelocity_2 -0.0007368600528827512 9.005287404956428e-07 -0.0022980320941459503
  hidden angularVelocity_2 -2.0140792242152178e-05 -0.0024381794220727556 8.402966219242269e-06
  hidden translation_3 0 0 0
  hidden rotation_3 0.9999999999999999 0 0 0.00523000721289873
  hidden linearVelocity_3 -0.00031209846570725745 7.190524125545655e-06 -0.007571999987422616
  hidden angularVelocity_3 -1.1367829006512852e-05 -0.0009844909016762417 8.011450328015902e-06
  hidden translation_4 0 0 0
  hidden rotation_4 -1 0 0 0.005376375780113023
  hidden linearVelocity_4 -0.00029917958140226607 7.19932998248203e-06 -0.0074536106649915265
  hidden angularVelocity_4 -1.1378471270509201e-05 -0.0009437493836986692 8.007577257694024e-06
  translation 29.461005822016624 -2.569925593437263 0.12448674063645976
  rotation -0.007723563733120022 -0.9999699052352493 -0.0007315648070854678 0.01660423729322654
  name "vehicle(1)"
}
WoodenChair {
  translation 0.605216 3.51175 0
  rotation 0 0 1 0.523599
}
